Workbook

Sheet 0. Resumen Ejecutivo
A1: PRESTAR LOS SERVICIOS DE TELECOMUNICACIONES DE RED CORPORATIVA WAN-LAN, SEGURIDAD INFORMÁTICA Y VIDEOCONFERENCIA PARA LA FISCALÍA GENERAL DE LA NACIÓN
A2: Servicios Gestionados TIC Integrales — Fiscalía General de la Nación | 36 meses | 876 sedes | 5 dominios técnicos
A3: ANEXO 4. FORMATO DE OFERTA ECONÓMICA - CUADRO DE COSTOS CONSOLIDADO
A4: Ítem | B4: Componente | C4: Hoja de detalle | D4: Valor (COP) | E4: % Costo Directo
A5: D1 | B5: DOMINIO 1 — Conectividad WAN-LAN SD-WAN | C5: 'D1. Conectividad' | D5: 1.1520732e+11 | E5: =D5/$D$11 -> 0.32950478
A6: D2 | B6: DOMINIO 2 — Seguridad Digital y Ciberseguridad | C6: 'D2. Seguridad' | D6: 1.0123187e+11 | E6: =D6/$D$11 -> 0.28953355
A7: D3 | B7: DOMINIO 3 — Videoconferencia (UCaaS + Hardware) | C7: 'D3. Videoconferencia' | D7: 5.2374834e+10 | E7: =D7/$D$11 -> 0.14979741
A8: D4 | B8: DOMINIO 4 — Cableado Estructurado (bolsa de puntos) | C8: 'D4. Cableado' | D8: 1.380646e+10 | E8: =D8/$D$11 -> 0.039487895
A9: P6 | B9: ANEXO 6 — Perfiles Profesionales (36 meses) | C9: 'P6. Perfiles' | D9: 5.60275e+10 | E9: =D9/$D$11 -> 0.1602444
A10: GG | B10: Gastos Generales, Transición y Administración | C10: 'GG. Gastos Generales' | D10: 1.0989803e+10 | E10: =D10/$D$11 -> 0.031431966
A11: TOTAL | D11: =+D5+D6+D7+D8+D9+D10 -> 3.4963779e+11 | E11: 100.0%
A13: VALOR TOTAL ESTIMADO DEL CONTRATO ARCANUS 2026 (36 MESES, IVA INCLUIDO Y TODOS LOS COSTOS DIRECTOS E INDIRECTOS A QUE HAYA LUGAR) | D13: =+D11 -> 3.4963779e+11
A14: Valor mensual promedio (sobre 36 meses, IVA incluido) | D14: =D13/'1. Parámetros'!$B$4 -> 9.7121609e+09
A15: Costo promedio por sede (876 sedes, 36 meses) | D15: =D13/'1. Parámetros'!$B$5 -> 3.991299e+08
A17: OBSERVACIONES PARA EL ESTUDIO DEL SECTOR
A18: • Esta proyección de costos constituye una estimación referencial para el ESTUDIO DEL SECTOR conforme al Decreto 1600 de 2024. Los valores unitarios deben validarse con MÍNIMO DOS (2) cotizaciones formales y consultas en SECOP II.
A19: • La modalidad de selección es LICITACIÓN PÚBLICA con adjudicación a un único proponente (o proponente plural), conforme lo justifica la integralidad del proyecto y la responsabilidad extremo a extremo sobre los ANS.
A20: • La forma de pago combina TRES esquemas: (a) tarifa mensual por servicios recurrentes (conectividad, seguridad, UCaaS), (b) pago contra entrega de hardware (soluciones VC, kits LEO), (c) bolsa de monto agotable (cableado por punto ejecutado).
A21: • Los ANS extremadamente exigentes (99.99% disponibilidad, RTO 8 minutos) y la responsabilidad extremo a extremo justifican el factor multiplicador y los porcentajes de administración/utilidad aplicados.
A22: • El esquema de coexistencia operacional con el proveedor saliente (10 meses) genera sobrecostos específicos contemplados en la sección de Transición.
A23: • La liquidación de pagos estará sujeta a ajustes económicos y créditos de servicio por incumplimiento de ANS, conforme al Anexo 5 — Acuerdos de Niveles de Servicio.
A24: • El presente cuadro NO incluye la interventoría del contrato (proceso independiente bajo Concurso de Méritos — ver cuadro de costos separado).

Sheet 1. Parámetros
A1: LICITACIÓN ARCANUS 2026 (FISCATEL) — PARÁMETROS Y SUPUESTOS
A3: Variable | B3: Valor | C3: Unidad | D3: Fuente / Justificación
A4: Plazo total del contrato | B4: 36 | C4: meses | D4: Anexo Técnico de Interventoría / Fase IV M13-M36
A5: Total de sedes a atender | B5: 876 | C5: sedes | D5: Anexo 1.1 Sedes (876 filas). NOTA: Anexo 2 S1.1.2 cita 877 y Anexo 7 cita 881 nodos - pendiente armonizar
A6: Sedes Cat 1 - Datacenters/Núcleo SD-WAN | B6: 2 | C6: nodos | D6: Bogotá Salitre + Cali Bunker (activo-activo)
A7: Sedes Cat 2 - Principales (capitales) | B7: 765 | C7: sedes | D7: AT1 Conectividad (matriz post-consolidación)
A8: Sedes Cat 3 - Intermedias (ciudades medianas) | B8: 86 | C8: sedes | D8: AT1 Conectividad
A9: Sedes Cat 4 - Remotas (LEO satelital) | B9: 25 | C9: sedes | D9: AT1 Conectividad - zonas sin fibra
A10: Sedes Cat 5 - Nubes públicas (canales) | B10: 4 | C10: canales | D10: Azure ExpressRoute + OCI FastConnect (2 c/u)
A11: Sedes Cat 6 - Canales complementarios | B11: 4 | C11: canales | D11: AT1 Conectividad Cat 6 - cantidad NO cuantificada en anexos (estimacion por confirmar)
A12: Usuarios SASE/SSE | B12: 30000 | C12: usuarios | D12: AT2 Seguridad - licenciamiento perimetral
A13: Endpoints con XDR/EDR | B13: 26000 | C13: endpoints | D13: AT2 Seguridad - estaciones de trabajo
A14: Servidores Antimalware | B14: 500 | C14: servidores | D14: AT2 Seguridad S10: 500 servidores aprox. (250 Linux / 250 Windows) [ajustado de 600]
A15: Activos monitoreados SOC | B15: 1500 | C15: activos | D15: AT2 Seguridad - monitoreo 24x7
... A35: Estudios formales de trafico (36 meses) | B35: 4 | C35: estudios | D35: AT1 C13.3: 1 linea base + 3 anuales [REFERENCIA: la hoja D1 item 6 usa 12 - ajuste pendiente de aprobacion]
A37: NOTAS METODOLÓGICAS
A38: 1. Los valores unitarios son referenciales de mercado para servicios gestionados TIC en Colombia 2026 — deben validarse con MÍNIMO DOS (2) cotizaciones formales según Decreto 1600 de 2024.
A39: 2. El factor multiplicador (1.85) aplica solo a perfiles profesionales y cubre prestaciones, parafiscales, dotación, capacitación, certificaciones, administración y utilidad del consultor.
A40: 3. Servicios recurrentes (conectividad, seguridad, plataforma UCaaS) se modelan como tarifa mensual × meses. Hardware (soluciones VC, kits LEO) se factura contra entrega.
A41: 4. Cableado se factura bajo modalidad BOLSA DE MONTO AGOTABLE: se paga por punto efectivamente instalado/reubicado.
A42: 5. Los costos de Cat 1 (datacenter) incluyen 2 canales Internet 5Gbps + 2 canales datos 5Gbps + 2 canales por nube pública.
A43: 6. Las cantidades estimadas para servicios por demanda (SASE, EDR, puntos) son MÁXIMOS referenciales, no obligaciones mínimas de consumo para la Entidad.
A44: 7. AJUSTES 31-07-2026 (solo hoja Parametros, validacion vs anexos): servidores 600->500 (S10); IPs escaneo 1.000->2.000 (S14.2.1). Se agregan como referencia NAC 35.000 conexiones (S9.4), DLP 30.000 usuarios (S8.2.2) y estudios de trafico 4 (C13.3), sin modificar las hojas D1/D2.
A46: CONVENCIONES DE COLOR
A47: Texto azul | B47: Entrada modificable (hardcoded input)
A48: Texto negro | B48: Fórmula calculada
A49: Texto verde | B49: Vínculo entre hojas
A50: Fondo verde claro | B50: Total / Subtotal
A51: Fondo azul navy | B51: Gran total / valor final del contrato

Sheet D1. Conectividad
A1: DOMINIO 1 — SERVICIO DE CONECTIVIDAD WAN-LAN (SD-WAN NACIONAL)
A2: Anexo Técnico 1 — Arquitectura SD-WAN activo-activo Bogotá-Cali / Cobertura 876 sedes / IPv6 dual-stack
A4: Ítem | B4: Servicio / Componente | C4: Unidad | D4: Cantidad | E4: Tarifa unitaria mensual (COP) | F4: Meses | G4: Costo total 36 meses (COP) | H4: Observaciones | J4: WEXLER S.A.S. | K4: COLOMBIA TELECOMUNICACIONES S.A. ESP BIC | L4: SONDA DE COLOMBIA S.A. | M4: COMUNICACION CELULAR S A COMCEL S A | N4: GROW DATA S.A.S | O4: MEDIA COMMERCE S.A.S. | P4: TESERACT S.A.S. | Q4: YEAPDATA S.A.S. | R4: S3 SIMPLE SMART SPEEDY S.A.S. | T4: COIZACIÓN MÁS BAJA | U4: COTIZACIÓN MÁS ALTA | V4: PROMEDIO | W4: MEDIA ARITMÉTICA BAJA
A5: A. SERVICIO SD-WAN RECURRENTE POR CATEGORÍA DE SEDE
A6: 1 | B6: Servicio Cat 1 — Datacenter / Núcleo SD-WAN (2x5Gbps Internet + 2x5Gbps Datos + 2x canal por nube) | C6: Nodo-mes | D6: ='1. Parámetros'!$B$6 -> 2 | E6: 1.3024189e+08 | F6: ='1. Parámetros'!$B$4 -> 36 | G6: =ROUND(D6*E6*F6,2) -> 9.3774158e+09 | H6: Bogotá Salitre + Cali Bunker (activo-activo) | J6: 66056300 | K6: 1.8170714e+08 | L6: 1.2617719e+08 | M6: 182000000 | N6: 171080000 | O6: 1.4487518e+08 | P6: 290836000 | Q6: 5580000 | R6: 15748500 | T6: =+MIN(K6,L6,M6,N6,O6) -> 1.2617719e+08 | U6: =+MAX(J6:R6) -> 290836000 | V6: =+ROUND(AVERAGE(K6,L6,M6,N6,O6,),2) -> 1.3430659e+08 | W6: =+ROUND(AVERAGE(V6,T6),2) -> 1.3024189e+08
A7: 2 | B7: Servicio Cat 2 — Sedes principales (fibra dedicada con redundancia 1:1, doble carrier) | C7: Sede-mes | D7: ='1. Parámetros'!$B$7 -> 765 | E7: 3127558.4 | F7: ='1. Parámetros'!$B$4 -> 36 | G7: =ROUND(D7*E7*F7,2) -> 8.6132959e+10 | H7: 765 sedes en capitales (post-consolidación) | J7: 1326917.3 | K7: 3836039.7 | L7: 7332780 | M7: 3250000 | N7: 3384835.1 | O7: 9580803.2 | P7: 5861600 | Q7: 3840000 | R7: 637000 | T7: =+MIN(J7,K7,M7,N7,Q7) -> 1326917.3 | U7: =+MAX(J7:R7) -> 9580803.2 | V7: =+ROUND(AVERAGE(J7,K7,M7,N7,Q7),2) -> 3127558.4 | W7: =+ROUND(AVERAGE(V7,T7),2) -> 2227237.8
A8: 3 | B8: Servicio Cat 3 — Redes metropolitanas / Ciudades intermedias (MPLS + Internet activo-activo) | C8: Sede-mes | D8: ='1. Parámetros'!$B$8 -> 86 | E8: 2434778.2 | F8: ='1. Parámetros'!$B$4 -> 36 | G8: =ROUND(D8*E8*F8,2) -> 7.5380734e+09 | H8: Sedes seccionales en ciudades medianas | J8: 1085659.6 | K8: 2624658.7 | L8: 8075340 | M8: 2850000 | N8: 3040000 | O8: 2573572.8 | P8: 5168000 | Q8: 5400000 | R8: 637000 | T8: =+MIN(J8,K8,M8,N8,O8) -> 1085659.6 | U8: =+MAX(J8:R8) -> 8075340 | V8: =+ROUND(AVERAGE(J8,K8,M8,N8,O8),2) -> 2434778.2 | W8: =+ROUND(AVERAGE(V8,T8),2) -> 1760218.9
A9: 4 | B9: Servicio Cat 4 — Satelital LEO empresarial (zonas sin fibra) | C9: Sede-mes | D9: ='1. Parámetros'!$B$9 -> 25 | E9: 1937643.9 | F9: ='1. Parámetros'!$B$4 -> 36 | G9: =ROUND(D9*E9*F9,2) -> 1743879519 | H9: Tipo Starlink Business / SES-O3b | J9: 2653834.5 | K9: 7268285.8 | L9: 3271905 | M9: 1450000 | N9: 1574187.4 | O9: 8163887.9 | P9: 2475200 | Q9: 11040000 | R9: 3126600 | T9: =+MIN(J9,L9,M9,N9,P9,R9) -> 1450000 | U9: =+MAX(J9:R9) -> 11040000 | V9: =+ROUND(AVERAGE(J9,L9,M9,N9,P9,R9),2) -> 2425287.8 | W9: =+ROUND(AVERAGE(V9,T9),2) -> 1937643.9
A10: 5 | B10: Servicio Cat 5 — Interconexión cloud (ExpressRoute + FastConnect + VPN B2B) | C10: Canal-mes | D10: ='1. Parámetros'!$B$10 -> 4 | E10: 45018608 | F10: ='1. Parámetros'!$B$4 -> 36 | G10: =ROUND(D10*E10*F10,2) -> 6.4826795e+09 | H10: Azure + OCI (2 canales por nube) | J10: 9650307.3 | K10: 48455238 | L10: 50122800 | M10: 47500000 | N10: 51046096 | O10: 42176990 | P10: 83313600 | Q10: 18600000 | R10: 4053000 | T10: =+MIN(K10,L10,M10,N10,O10) -> 42176990 | U10: =+MAX(J10:R10) -> 83313600 | V10: =+ROUND(AVERAGE(K10,L10,M10,N10,O10),2) -> 47860225 | W10: =+ROUND(AVERAGE(V10,T10),2) -> 45018608
A11: 6 | B11: Servicio Cat 6 — Canales complementarios (Internet respaldo, móvil, WiFi) | C11: Canal-mes | D11: ='1. Parámetros'!$B$11 -> 4 | E11: 1991373.2 | F11: ='1. Parámetros'!$B$4 -> 36 | G11: =ROUND(D11*E11*F11,2) -> 2.8675774e+08 | H11: Bolsa de servicios complementarios | J11: 1447546.1 | K11: 12113810 | L11: 16707600 | M11: 3800000 | N11: 4125494.6 | O11: 1870937.6 | P11: 6800000 | Q11: 2520000 | R11: 1447500 | T11: =+MIN(J11:R11) -> 1447500 | U11: =+MAX(J11:R11) -> 16707600 | V11: =+ROUND(AVERAGE(J11,M11,N11,O11,Q11,R11),2) -> 2535246.4 | W11: =+ROUND(AVERAGE(V11,T11),2) -> 1991373.2
A12: Subtotal A — Servicio SD-WAN recurrente | G12: =SUM(G6:G11) -> 1.1156176e+11
A14: B. SERVICIOS Y COMPONENTES ADICIONALES DE CONECTIVIDAD
A15: 1 | B15: Solución móvil LEO para jornadas de descongestión / brigadas de justicia | C15: Kit | D15: 20 | E15: 9451946.5 | F15: 1 | G15: =ROUND(D15*E15*F15,2) -> 1.8903893e+08 | H15: Pago contra entrega - hardware + activación | J15: 18094326 | K15: 15126361 | L15: 39680550 | M15: 7500000 | N15: 8134909.8 | O15: 15662080 | P15: 13940000 | Q15: 10200000 | R15: 9263900 | T15: =+MIN(J15:R15) -> 7500000 | U15: =+MAX(J15:R15) -> 39680550 | V15: =+ROUND(AVERAGE(K15,M15,N15,O15,P15,Q15,R15),2) -> 11403893 | W15: =+ROUND(AVERAGE(V15,T15),2) -> 9451946.5
A16: 2 | B16: Servicio mensual conectividad LEO móvil (post-instalación) | C16: Kit-mes | D16: 20 | E16: 1594331.3 | F16: 36 | G16: =D16*E16*F16 -> 1.1479185e+09 | H16: Tarifa de servicio una vez activado | J16: 1447546.1 | K16: 5245790 | L16: 2436525 | M16: 1265000 | N16: 1398666.7 | O16: 2736000 | P16: 2271200 | Q16: 4200000 | R16: 1910700 | T16: =+MIN(J16:R16) -> 1265000 | U16: =+MAX(J16:R16) -> 5245790 | V16: =+ROUND(AVERAGE(J16,L16,M16,N16,O16,P16,R16),2) -> 1923662.6 | W16: =+ROUND(AVERAGE(V16,T16),2) -> 1594331.3
A17: 3 | B17: Adquisición y renovación Pool IPv6 /44 + ASN propio FGN | C17: Global | D17: 1 | E17: 25281754 | F17: 1 | G17: =D17*E17*F17 -> 25281754 | H17: Una sola vez - registro LACNIC | J17: 30157210 | K17: 32303492 | L17: 80753400 | M17: 24500000 | N17: 28288840 | O17: 45235200 | P17: 49640000 | Q17: 144000000 | R17: 22928000 | T17: =+MIN(J17:R17) -> 22928000 | U17: =+MAX(J17:R17) -> 144000000 | V17: =+ROUND(AVERAGE(J17,K17,M17,N17,R17),2) -> 27635509 | W17: =+ROUND(AVERAGE(V17,T17),2) -> 25281754
A18: 4 | B18: Plataforma de monitoreo Anexo 1 C11 (licenciamiento incluido en CPE) | C18: Servicio-mes | D18: 1 | E18: 52897979 | F18: 36 | G18: =D18*E18*F18 -> 1.9043272e+09 | H18: Observabilidad de red | J18: 72377305 | K18: 10094841 | L18: 58476600 | M18: 45500000 | N18: 53300814 | O18: 71825067 | P18: 89896000 | Q18: 18000000 | R18: 9263900 | T18: =+MIN(J18,L18,M18,N18,O18,P18) -> 45500000 | U18: =+MAX(J18:R18) -> 89896000 | V18: =+ROUND(AVERAGE(J18,L18,M18,N18,O18),2) -> 60295957 | W18: =+ROUND(AVERAGE(V18,T18),2) -> 52897979
A19: 5 | B19: Servicio de ampliación de ancho de banda por demanda (bolsa anual) | C19: Bolsa-año | D19: 3 | E19: 71364184 | F19: 1 | G19: =D19*E19*F19 -> 2.1409255e+08 | H19: Crecimientos según demanda FGN | J19: 6.0314421e+08 | K19: 2.0189683e+08 | L19: 334152000 | M19: 45000000 | N19: 47549538 | O19: 114000000 | P19: 78907200 | Q19: 252000000 | R19: 578988500 | T19: =+MIN(J19:R19) -> 45000000 | U19: =+MAX(J19:R19) -> 6.0314421e+08 | V19: =+ROUND(AVERAGE(M19,N19,O19,P19),2) -> 71364184 | W19: =+ROUND(AVERAGE(V19,T19),2) -> 58182092
A20: 6 | B20: Estudios formales de tráfico / capacidad (trimestrales) | C20: Estudio | D20: 12 | E20: 13741774 | F20: 1 | G20: =D20*E20*F20 -> 1.6490128e+08 | H20: Caracterización 6/12/24 meses por categoría | J20: 18094326 | K20: 14132778 | L20: 17403750 | M20: 11500000 | N20: 12061177 | O20: 19000000 | P20: 19692800 | Q20: 30000000 | R20: 28949500 | T20: =+MIN(J20:R20) -> 11500000 | U20: =+MAX(J20:R20) -> 30000000 | V20: =+ROUND(AVERAGE(J20,K20,L20,M20,N20,O20,P20),2) -> 15983547 | W20: =+ROUND(AVERAGE(V20,T20),2) -> 13741774
A21: Subtotal B — Servicios y componentes adicionales | G21: =SUM(G15:G20) -> 3.6455603e+09
A23: TOTAL DOMINIO 1 — CONECTIVIDAD WAN-LAN | G23: =G12+G21 -> 1.1520732e+11

Sheet D2. Seguridad
A1: DOMINIO 2 — SEGURIDAD DIGITAL Y CIBERSEGURIDAD (SASE/SSE + SOC 24x7)
A2: Anexo Técnico 2 — Arquitectura SASE/SSE / SOC 24x7 / SIEM-SOAR / EDR-XDR / NAC / PAM / DLP
A4: Ítem | B4: Servicio / Componente | C4: Unidad | D4: Cantidad | E4: Tarifa unitaria mensual (COP) | F4: Meses | G4: Costo total 36 meses (COP) | H4: Observaciones | J4: WEXLER S.A.S. | K4: COLOMBIA TELECOMUNICACIONES S.A. ESP BIC | L4: SONDA DE COLOMBIA S.A. | M4: COMUNICACION CELULAR S A COMCEL S A | N4: GROW DATA S.A.S | O4: MEDIA COMMERCE S.A.S. | P4: TESERACT S.A.S. | Q4: YEAPDATA S.A.S. | R4: S3 SIMPLE SMART SPEEDY S.A.S. | T4: COIZACIÓN MÁS BAJA | U4: COTIZACIÓN MÁS ALTA | V4: PROMEDIO | W4: MEDIA ARITMÉTICA BAJA
A5: A. PLATAFORMA SASE/SSE Y PROTECCIÓN PERIMETRAL
A6: 1 | B6: Licenciamiento SASE/SSE por usuario (SWG + CASB + ZTNA + DLP) | C6: Usuario-mes | D6: ='1. Parámetros'!$B$12 -> 30000 | E6: 32867.37 | F6: ='1. Parámetros'!$B$4 -> 36 | G6: =ROUND(D6*E6*F6,2) -> 35496759600 | H6: 30.000 usuarios | J6: 50664.11 | K6: 39916.296 | L6: 42613.221 | M6: 45000 | N6: 55429.444 | O6: 25080 | P6: 65000 | Q6: 10200 | R6: 9300 | T6: =+MIN(J6,K6,L6,M6,O6) -> 25080 | U6: =+MAX(J6:R6) -> 65000 | V6: =+ROUND(AVERAGE(J6,K6,L6,M6,O6),2) -> 40654.73 | W6: =+ROUND(AVERAGE(T6,V6),2) -> 32867.37
A7: 2 | B7: Antimalware + XDR para endpoints (estaciones de trabajo) | C7: Endpoint-mes | D7: ='1. Parámetros'!$B$13 -> 26000 | E7: 15820.74 | F7: ='1. Parámetros'!$B$4 -> 36 | G7: =ROUND(D7*E7*F7,2) -> 14808212640 | H7: 26.000 endpoints | J7: 31363.5 | K7: 12039.912 | L7: 7349.7 | M7: 29500 | N7: 35393 | O7: 17480 | P7: 54400 | Q7: 25200 | R7: 5900 | T7: =+MIN(K7,L7,M7,O7,Q7) -> 7349.7 | U7: =+MAX(J7:R7) -> 54400 | V7: =+ROUND(AVERAGE(J7,K7,L7,M7,N7,O7,P7,Q7,R7),2) -> 24291.79 | W7: =+ROUND(AVERAGE(T7,V7),2) -> 15820.74
A8: 3 | B8: Antimalware para servidores (Windows / Linux) | C8: Servidor-mes | D8: ='1. Parámetros'!$B$14 -> 500 | E8: 38664.95 | F8: ='1. Parámetros'!$B$4 -> 36 | G8: =ROUND(D8*E8*F8,2) -> 695969100 | H8: 600 servidores | J8: 108565.95 | K8: 45149.52 | L8: 94210.071 | M8: 40000 | N8: 85142.591 | O8: 30400 | P8: 60000 | Q8: 156000 | R8: 59100 | T8: =+MIN(J8:R8) -> 30400 | U8: =+MAX(J8:R8) -> 156000 | V8: =+ROUND(AVERAGE(K8,M8,O8,P8,R8),2) -> 46929.9 | W8: =+ROUND(AVERAGE(T8,V8),2) -> 38664.95
A9: 4 | B9: Protección DDoS y NGFW perimetral (gestionado) | C9: Plataforma-mes | D9: 1 | E9: 1.7265626e+08 | F9: ='1. Parámetros'!$B$4 -> 36 | G9: =ROUND(D9*E9*F9,2) -> 6.2156255e+09 | H9: Inspección perímetro a 10 Gbps | J9: 4.2220095e+08 | K9: 1.8059807e+08 | L9: 6.4960759e+08 | M9: 340000000 | N9: 364656562 | O9: 60800000 | P9: 450000000 | Q9: 216000000 | R9: 104218000 | T9: =+MIN(K9,M9,N9,Q9,R9) -> 104218000 | U9: =+MAX(J9:R9) -> 6.4960759e+08 | V9: =+ROUND(AVERAGE(K9,M9,N9,Q9,R9),2) -> 2.4109453e+08 | W9: =+ROUND(AVERAGE(T9,V9),2) -> 1.7265626e+08
A10: 5 | B10: Gestión y administración de WAF Radware existentes | C10: Dispositivo-mes | D10: ='1. Parámetros'!$B$17 -> 4 | E10: 5312627.7 | F10: ='1. Parámetros'!$B$4 -> 36 | G10: =ROUND(D10*E10*F10,2) -> 7.6501838e+08 | H10: 4 dispositivos WAF FGN | J10: 9650307.3 | K10: 3511629.1 | L10: 1.9246375e+08 | M10: 6249000 | N10: 7008173.5 | O10: 9120000 | P10: 8500000 | Q10: 6120000 | R10: 6749900 | T10: =+MIN(J10:R10) -> 3511629.1 | U10: =+MAX(J10:R10) -> 1.9246375e+08 | V10: =+ROUND(AVERAGE(J10,K10,M10,N10,O10,P10,Q10,R10),2) -> 7113626.2 | W10: =+ROUND(AVERAGE(T10,V10),2) -> 5312627.7
A11: 6 | B11: WAF como servicio adicional para apps cloud | C11: App-mes | D11: 1 | E11: 30614255 | F11: ='1. Parámetros'!$B$4 -> 36 | G11: =ROUND(D11*E11*F11,2) -> 1.1021132e+09 | H11: Bolsa para apps SaaS críticas | J11: 48251537 | K11: 5016612.9 | L11: 85073479 | M11: 125000000 | N11: 1.4207893e+08 | O11: 6080000 | P11: 170000000 | Q11: 30000000 | R11: 9263900 | T11: =+MIN(J11:R11) -> 5016612.9 | U11: =+MAX(J11:R11) -> 170000000 | V11: =+ROUND(AVERAGE(J11,K11,L11,O11,Q11,R11),2) -> 30614255 | W11: =+ROUND(AVERAGE(T11,V11),2) -> 17815434
A12: Subtotal A — SASE/SSE y Protección Perimetral | G12: =SUM(G6:G11) -> 5.9083698e+10
A14: B. SOC 24x7 — SIEM / SOAR / NDR / PAM / NAC / DLP
A15: 1 | B15: SOC 24x7 — Operación gestionada (turnos N1/N2/N3, runbooks, threat hunting) | C15: Servicio-mes | D15: 1 | E15: 82508344 | F15: ='1. Parámetros'!$B$4 -> 36 | G15: =ROUND(D15*E15*F15,2) -> 2970300366 | H15: Centro de Operaciones de Seguridad | J15: 3.015721e+08 | K15: 1.2039871e+08 | L15: 1.7199e+08 | M15: 72500000 | N15: 77563212 | O15: 155800000 | P15: 90000000 | Q15: 102000000 | R15: 92638200 | T15: =+MIN(J15:R15) -> 72500000 | U15: =+MAX(J15:R15) -> 3.015721e+08 | V15: =+ROUND(AVERAGE(K15,M15,N15,P15,Q15,R15),2) -> 92516687 | W15: =+ROUND(AVERAGE(T15,V15),2) -> 82508344
A16: 2 | B16: SIEM — Licenciamiento por EPS (eventos por segundo) e ingesta de logs | C16: Plataforma-mes | D16: 1 | E16: 72482252 | F16: ='1. Parámetros'!$B$4 -> 36 | G16: =ROUND(D16*E16*F16,2) -> 2.6093611e+09 | H16: Ingestión multifuente / retención 36 meses | J16: 3.6188652e+08 | K16: 45149516 | L16: 91960555 | M16: 85000000 | N16: 92883461 | O16: 62320000 | P16: 105000000 | Q16: 264000000 | R16: 81058500 | T16: =+MIN(L16,M16,N16,O16,R16) -> 62320000 | U16: =+MAX(J16:R16) -> 3.6188652e+08 | V16: =+ROUND(AVERAGE(L16,M16,N16,O16,R16),2) -> 82644503 | W16: =+ROUND(AVERAGE(T16,V16),2) -> 72482252
A17: 3 | B17: SOAR — Plataforma de orquestación y respuesta automatizada | C17: Plataforma-mes | D17: 1 | E17: 39662531 | F17: ='1. Parámetros'!$B$4 -> 36 | G17: =ROUND(D17*E17*F17,2) -> 1.4278511e+09 | H17: Playbooks integrados con ITSM | J17: 96503073 | K17: 25083065 | L17: 64887618 | M17: 74500000 | N17: 82996926 | O17: 19000000 | P17: 95000000 | Q17: 72000000 | R17: 34739300 | T17: =+MIN(K17,L17,M17,Q17,R17) -> 25083065 | U17: =+MAX(J17:R17) -> 96503073 | V17: =+ROUND(AVERAGE(K17,L17,M17,Q17,R17),2) -> 54241997 | W17: =+ROUND(AVERAGE(T17,V17),2) -> 39662531
A18: 4 | B18: NDR — Network Detection & Response (sensores en sedes Cat 1) | C18: Servicio-mes | D18: 1 | E18: 35855728 | F18: ='1. Parámetros'!$B$4 -> 36 | G18: =ROUND(D18*E18*F18,2) -> 1.2908062e+09 | H18: Detección lateral en datacenter | J18: 72377305 | K18: 18059807 | L18: 1.1059012e+08 | M18: 57500000 | N18: 60497383 | O18: 22800000 | P18: 74500000 | Q18: 54000000 | R18: 69478700 | T18: =+MIN(J18:R18) -> 18059807 | U18: =+MAX(J18:R18) -> 1.1059012e+08 | V18: =+ROUND(AVERAGE(J18,K18,M18,N18,O18,P18,Q18,R18),2) -> 53651649 | W18: =+ROUND(AVERAGE(T18,V18),2) -> 35855728
A19: 5 | B19: Monitoreo de activos críticos (1.500 activos monitoreados) | C19: Activo-mes | D19: ='1. Parámetros'!$B$15 -> 1500 | E19: 30708.79 | F19: ='1. Parámetros'!$B$4 -> 36 | G19: =ROUND(D19*E19*F19,2) -> 1658274660 | H19: Servidores, bases de datos, apps misionales | J19: 30157.21 | K19: 25083.06 | L19: 6409.8289 | M19: 45000 | N19: 49926.838 | O19: 25840 | P19: 61600 | Q19: 42000 | R19: 11600 | T19: =+MIN(J19,K19,N19,M19,O19,Q19) -> 25083.06 | U19: =+MAX(J19:R19) -> 61600 | V19: =+ROUND(AVERAGE(J19,K19,M19,N19,O19,Q19),2) -> 36334.52 | W19: =+ROUND(AVERAGE(T19,V19),2) -> 30708.79
A20: 6 | B20: PAM — Privileged Access Management (gestión de accesos privilegiados) | C20: Servicio-mes | D20: 1 | E20: 35058424 | F20: ='1. Parámetros'!$B$4 -> 36 | G20: =ROUND(D20*E20*F20,2) -> 1.2621033e+09 | H20: Gestión de cuentas privilegiadas | J20: 84440189 | K20: 30099678 | L20: 35511017 | M20: 36500000 | N20: 39370404 | O20: 43320000 | P20: 49000000 | Q20: 60000000 | R20: 46319100 | T20: =+MIN(J20:R20) -> 30099678 | U20: =+MAX(J20:R20) -> 84440189 | V20: =+ROUND(AVERAGE(K20,L20,M20,N20,O20,P20,R20),2) -> 40017171 | W20: =+ROUND(AVERAGE(T20,V20),2) -> 35058424
A21: 7 | B21: NAC — Network Access Control (control de acceso a la red) | C21: Usuario-mes | D21: ='1. Parámetros'!$B$12 -> 30000 | E21: 14575.27 | F21: ='1. Parámetros'!$B$4 -> 36 | G21: =ROUND(D21*E21*F21,2) -> 15741291600 | H21: Integrado con AD/IdP | J21: 7237.74 | K21: 20066.448 | L21: 63919.831 | M21: 85000 | N21: 125184.94 | O21: 8740 | P21: 117000 | Q21: 9600 | R21: 4600 | T21: =+MIN(J21,K21,L21,M21,O21,Q21) -> 7237.74 | U21: =+MAX(J21:R21) -> 125184.94 | V21: =+ROUND(AVERAGE(J21,K21,L21,O21,Q21),2) -> 21912.8 | W21: =+ROUND(AVERAGE(T21,V21),2) -> 14575.27
A22: 8 | B22: DLP — Data Loss Prevention (endpoint + M365 + SSE + Discovery) | C22: Endpoint-mes | D22: ='1. Parámetros'!$B$13 -> 26000 | E22: 12629.8 | F22: ='1. Parámetros'!$B$4 -> 36 | G22: =ROUND(D22*E22*F22,2) -> 11821492800 | H22: Catálogo inicial 25 políticas | J22: 10856.59 | K22: 15049.836 | L22: 16128.615 | M22: 65000 | N22: 99300.102 | O22: 15580 | P22: 83000 | Q22: 14400 | R22: 5900 | T22: =+MIN(J22,K22,L22,O22,Q22) -> 10856.59 | U22: =+MAX(J22:R22) -> 99300.102 | V22: =+ROUND(AVERAGE(J22,K22,L22,O22,Q22),2) -> 14403.01 | W22: =+ROUND(AVERAGE(T22,V22),2) -> 12629.8
A23: 9 | B23: Vigilancia digital Clear/Deep/Dark Web (CTI - Threat Intelligence) | C23: Servicio-mes | D23: 1 | E23: 25121595 | F23: ='1. Parámetros'!$B$4 -> 36 | G23: =ROUND(D23*E23*F23,2) -> 904377429 | H23: Monitoreo de marca FGN | J23: 54282979 | K23: 10033226 | L23: 2.0111194e+08 | M23: 65500000 | N23: 69514148 | O23: 11400000 | P23: 89500 | Q23: 36000000 | R23: 34739400 | T23: =+MIN(J23,K23,M23,N23,O23,Q23,R23) -> 10033226 | U23: =+MAX(J23:R23) -> 2.0111194e+08 | V23: =+ROUND(AVERAGE(J23,K23,M23,N23,O23,Q23,R23),2) -> 40209965 | W23: =+ROUND(AVERAGE(T23,V23),2) -> 25121595
A24: 10 | B24: Escaneo recurrente de vulnerabilidades internas | C24: IP-mes | D24: ='1. Parámetros'!$B$16 -> 2000 | E24: 11670.71 | F24: ='1. Parámetros'!$B$4 -> 36 | G24: =ROUND(D24*E24*F24,2) -> 840291120 | H24: 1.000 IPs escaneadas | J24: 18094.33 | K24: 8026.584 | L24: 614.41084 | M24: 18000 | N24: 19995.721 | O24: 8360 | P24: 35000 | Q24: 24427.2 | R24: 10300 | T24: =+MIN(J24,K24,M24,N24,O24,Q24,R24) -> 8026.584 | U24: =+MAX(J24:R24) -> 35000 | V24: =+ROUND(AVERAGE(J24,K24,M24,N24,O24,Q24,R24),2) -> 15314.83 | W24: =+ROUND(AVERAGE(T24,V24),2) -> 11670.71
A25: 11 | B25: Escaneo de vulnerabilidades perímetro/externo | C25: Servicio-mes | D25: 1 | E25: 12406272 | F25: ='1. Parámetros'!$B$4 -> 36 | G25: =ROUND(D25*E25*F25,2) -> 4.4662578e+08 | H25: Activos expuestos a Internet | J25: 24125768 | K25: 5016612.9 | L25: 52554407 | M25: 24300000 | N25: 26645261 | O25: 7600000 | P25: 37500000 | Q25: 21600000 | R25: 11579800 | T25: =+MIN(J25:R25) -> 5016612.9 | U25: =+MAX(J25:R25) -> 52554407 | V25: =+ROUND(AVERAGE(J25,K25,M25,N25,O25,P25,Q25,R25),2) -> 19795930 | W25: =+ROUND(AVERAGE(T25,V25),2) -> 12406272
A26: 12 | B26: Servicio de Correo Seguro (Protección de Correo Electrónico Basada en Nube) | C26: Servicio-mes | D26: 1 | E26: 26610028 | F26: 36 | G26: =ROUND(D26*E26*F26,2) -> 9.5796102e+08 | H26: Correo analizado y seguro | J26: 1.0856596e+08 | K26: 9197123.7 | L26: 11592884 | M26: 190000000 | N26: 215000000 | O26: 21280000 | P26: 245000000 | Q26: 180000000 | R26: 69478700 | T26: =+MIN(J26:R26) -> 9197123.7 | U26: =+MAX(J26:R26) -> 245000000 | V26: =+ROUND(AVERAGE(J26,K26,L26,O26,R26),2) -> 44022933 | W26: =+ROUND(AVERAGE(T26,V26),2) -> 26610028
A27: 13 | B27: Pruebas de Penetración (Pentesting) — campañas semestrales | C27: Ejecución | D27: ='1. Parámetros'!$B$26 -> 6 | E27: 36239212 | F27: 1 | G27: =ROUND(D27*E27*F27,2) -> 2.1743527e+08 | H27: 6 campañas / 36 meses (NIST 800-115) | J27: 2.1713191e+08 | K27: 80265807 | M27: 32740000 | N27: 36186314 | O27: 26600000 | P27: 53600000 | Q27: 222000000 | R27: 138957300 | T27: =+MIN(J27:R27) -> 26600000 | U27: =+MAX(J27:R27) -> 222000000 | V27: =+ROUND(AVERAGE(K27,M27,N27,O27,P27),2) -> 45878424 | W27: =+ROUND(AVERAGE(T27,V27),2) -> 36239212
A28: Subtotal B — SOC 24x7 y Servicios Gestionados de Ciberseguridad | G28: =SUM(G15:G27) -> 4.2148172e+10
A30: TOTAL DOMINIO 2 — SEGURIDAD DIGITAL Y CIBERSEGURIDAD | G30: =G12+G28 -> 1.0123187e+11

Sheet D3. Videoconferencia
A1: DOMINIO 3 — SERVICIO DE VIDEOCONFERENCIA (UCAAS + HARDWARE DE SALAS)
A2: Anexo Técnico 3 — Plataforma UCaaS SaaS/Híbrida / 86 salas / Webinars 2.000+ asistentes / Cert. NDAA
A4: Ítem | B4: Servicio / Componente | C4: Unidad | D4: Cantidad | E4: Tarifa unitaria mensual (COP) | F4: Meses | G4: Costo total 36 meses (COP) | H4: Observaciones | J4: WEXLER S.A.S. | K4: COLOMBIA TELECOMUNICACIONES S.A. ESP BIC | L4: SONDA DE COLOMBIA S.A. | M4: COMUNICACION CELULAR S A COMCEL S A | N4: GROW DATA S.A.S | O4: MEDIA COMMERCE S.A.S. | P4: TESERACT S.A.S. | Q4: YEAPDATA S.A.S. | R4: S3 SIMPLE SMART SPEEDY S.A.S. | T4: COIZACIÓN MÁS BAJA | U4: COTIZACIÓN MÁS ALTA | V4: PROMEDIO | W4: MEDIA ARITMÉTICA BAJA
A5: A. PLATAFORMA UCAAS — LICENCIAMIENTO Y SERVICIO RECURRENTE
A6: 1 | B6: Plataforma UCaaS (SaaS/Híbrida) — licenciamiento usuario reuniones estándar | C6: Usuario-mes | D6: ='1. Parámetros'!$B$12 -> 30000 | E6: 43219.73 | F6: ='1. Parámetros'!$B$4 -> 36 | G6: =ROUND(D6*E6*F6,2) -> 46677308400 | H6: 30.000 usuarios FGN | J6: 14475.46 | K6: 28754 | L6: 231378.73 | M6: 150000 | N6: 163274.5 | O6: 21280 | P6: 205000 | Q6: 54000 | R6: 5900 | T6: =+MIN(J6,K6,M6,N6,O6,Q6) -> 14475.46 | U6: =+MAX(J6:R6) -> 231378.73 | V6: =+ROUND(AVERAGE(J6,K6,M6,N6,O6,Q6),2) -> 71963.99 | W6: =+ROUND(AVERAGE(T6,V6),2) -> 43219.73
A7: 2 | B7: Licenciamiento Webinar (2.000+ participantes concurrentes) | C7: Plataforma-mes | D7: 1 | E7: 22716167 | F7: ='1. Parámetros'!$B$4 -> 36 | G7: =ROUND(D7*E7*F7,2) -> 8.1778203e+08 | H7: Audiencias virtuales / streaming integrado | J7: 30157210 | K7: 14220000 | L7: 22684189 | M7: 45500000 | N7: 48112610 | O7: 26600000 | P7: 81137600 | Q7: 5.8136247e+08 | R7: 1771800 | T7: =+MIN(J7:O7) -> 14220000 | U7: =+MAX(J7:R7) -> 5.8136247e+08 | V7: =+ROUND(AVERAGE(J7,K7,L7,M7,N7,O7),2) -> 31212335 | W7: =+ROUND(AVERAGE(T7,V7),2) -> 22716167
A8: 3 | B8: Repositorio de grabaciones con retención permanente y portal | C8: Plataforma-mes | D8: 1 | E8: 18826008 | F8: ='1. Parámetros'!$B$4 -> 36 | G8: =ROUND(D8*E8*F8,2) -> 6.777363e+08 | H8: Mediateca + transcripción + DLP integrado | J8: 24125768 | K8: 8520734 | L8: 11342095 | M8: 92100000 | N8: 95683611 | O8: 36480000 | P8: 153557600 | Q8: 48000000 | R8: 46319100 | T8: =+MIN(J8:R8) -> 8520734 | U8: =+MAX(J8:R8) -> 153557600 | V8: =+ROUND(AVERAGE(J8,K8,L8,O8,Q8,R8),2) -> 29131283 | W8: =+ROUND(AVERAGE(T8,V8),2) -> 18826008
A9: 4 | B9: Soporte técnico en sitio para eventos críticos / 250 servicios/mes | C9: Servicio-mes | D9: 1 | E9: 44834490 | F9: ='1. Parámetros'!$B$4 -> 36 | G9: =ROUND(D9*E9*F9,2) -> 1614041622 | H9: Operadores VC (perfil P5 - ver hoja Perfiles) | J9: 36188652 | K9: 74988500 | L9: 1.1703024e+08 | M9: 95000000 | N9: 99869700 | O9: 60040000 | P9: 157556000 | Q9: 30000000 | R9: 28949500 | T9: =+MIN(J9:R9) -> 28949500 | U9: =+MAX(J9:R9) -> 157556000 | V9: =+ROUND(AVERAGE(J9,K9,M9,N9,O9,Q9,R9),2) -> 60719479 | W9: =+ROUND(AVERAGE(T9,V9),2) -> 44834490
A10: 5 | B10: Integración con Microsoft Teams + AD/IdP institucional | C10: Plataforma-mes | D10: 1 | E10: 7687249.3 | F10: ='1. Parámetros'!$B$4 -> 36 | G10: =ROUND(D10*E10*F10,2) -> 2.7674098e+08 | H10: Interoperabilidad UCaaS-Teams | J10: 18094326 | K10: 3998466.7 | L10: 3402628.4 | M10: 120000000 | N10: 125588400 | O10: 14440000 | P10: 2.1692e+08 | Q10: 18000000 | R10: 13895800 | T10: =+MIN(J10:R10) -> 3402628.4 | U10: =+MAX(J10:R10) -> 2.1692e+08 | V10: =+ROUND(AVERAGE(J10,K10,L10,O10,Q10,R10),2) -> 11971870 | W10: =+ROUND(AVERAGE(T10,V10),2) -> 7687249.3
A11: Subtotal A — Plataforma UCaaS | G11: =SUM(G6:G10) -> 5.0063609e+10
A13: B. HARDWARE DE SALAS DE VIDEOCONFERENCIA (PAGO CONTRA ENTREGA)
A14: 1 | B14: Solución Tipo 1 — DJT: Pantalla interactiva 55" + 2 cámaras PTZ + 2 micrófonos + tablet + asistente | C14: Solución | D14: ='1. Parámetros'!$B$18 -> 31 | E14: 16291166 | F14: 1 | G14: =ROUND(D14*E14*F14,2) -> 5.0502615e+08 | H14: Justicia Transicional - 31 salas | J14: 66345863 | K14: 95280639 | L14: 2.7365498e+08 | M14: 6230000 | N14: 7600000 | O14: 22800000 | P14: 9751200 | Q14: 45386932 | R14: 92638200 | T14: =+MIN(J14:R14) -> 6230000 | U14: =+MAX(J14:R14) -> 2.7365498e+08 | V14: =+ROUND(AVERAGE(J14,M14,N14,O14,P14,Q14),2) -> 26352332 | W14: =+ROUND(AVERAGE(T14,V14),2) -> 16291166
A15: 2 | B15: Solución Tipo 2 — Auditorios: Códec VC + 2 cámaras PTZ + tablet + asistente | C15: Solución | D15: ='1. Parámetros'!$B$19 -> 7 | E15: 17347916 | F15: 1 | G15: =ROUND(D15*E15*F15,2) -> 1.2143541e+08 | H15: Auditorios principales - 7 salas | J15: 54282979 | K15: 78280640 | L15: 2.2947635e+08 | M15: 1285000 | N15: 2450000 | O15: 26600000 | P15: 2121600 | Q15: 1.4357091e+08 | R15: 110007800 | T15: =+MIN(J15:R15) -> 1285000 | U15: =+MAX(J15:R15) -> 2.2947635e+08 | V15: =+ROUND(AVERAGE(J15,M15,N15,O15,P15),2) -> 17347916 | W15: =+ROUND(AVERAGE(T15,V15),2) -> 9316457.9
A16: 3 | B16: Solución Tipo 3 — Móviles: Códec + 2 PTZ + 4 micrófonos + tablet + asistente + tótem LED 55" | C16: Solución | D16: ='1. Parámetros'!$B$20 -> 3 | E16: 13594125 | F16: 1 | G16: =ROUND(D16*E16*F16,2) -> 40782375 | H16: Kit móvil con tótem - 3 unidades | J16: 84440189 | K16: 114650500 | L16: 2.4243424e+08 | M16: 4205550 | N16: 6700550 | O16: 36480000 | P16: 6990400 | Q16: 5.8624787e+08 | R16: 162116800 | T16: =+MIN(J16:R16) -> 4205550 | U16: =+MAX(J16:R16) -> 5.8624787e+08 | V16: =+ROUND(AVERAGE(M16,N16,O16,P16),2) -> 13594125 | W16: =+ROUND(AVERAGE(T16,V16),2) -> 8899837.5
A17: 4 | B17: Solución Tipo 4 — Direcciones: Pantalla interactiva 55" con carro móvil + cámara PTZ + micrófono + tablet | C17: Solución | D17: ='1. Parámetros'!$B$21 -> 45 | E17: 18611200 | F17: 1 | G17: =ROUND(D17*E17*F17,2) -> 837504000 | H17: Direcciones y Subdirecciones - 45 salas | J17: 42220095 | K17: 89136458 | L17: 2.0559841e+08 | M17: 12540000 | N17: 18540000 | O17: 22040000 | P17: 21324800 | Q17: 46899829 | R17: 156327000 | T17: =+MIN(J17:R17) -> 12540000 | U17: =+MAX(J17:R17) -> 2.0559841e+08 | V17: =+ROUND(AVERAGE(M17,N17,O17,P17),2) -> 18611200 | W17: =+ROUND(AVERAGE(T17,V17),2) -> 15575600
A18: 5 | B18: Kit de Soporte (Tipo 1, 3 y 4) — Repuestos y elementos de respaldo | C18: Kit | D18: ='1. Parámetros'!$B$22 -> 7 | E18: 16954995 | F18: 1 | G18: =ROUND(D18*E18*F18,2) -> 1.1868497e+08 | H18: 7 kits de soporte / repuestos | J18: 18094326 | K18: 17197575 | L18: 14883074 | M18: 14800000 | N18: 19800000 | O18: 7524000 | P18: 23147200 | Q18: 40199854 | R18: 40529300 | T18: =+MIN(J18,K18,L18,M18,N18,P18) -> 14800000 | U18: =+MAX(J18:R18) -> 40529300 | V18: =+ROUND(AVERAGE(J18,K18,L18,M18,N18),2) -> 16954995 | W18: =+ROUND(AVERAGE(T18,V18),2) -> 15877498
A19: 6 | B19: Instalación, configuración y puesta en marcha de salas | C19: Sala | D19: 86 | E19: 7997582.6 | F19: 1 | G19: =ROUND(D19*E19*F19,2) -> 6.8779211e+08 | H19: Por cada sala instalada (servicio profesional) | J19: 7237730.5 | K19: 18688032 | L19: 13618526 | M19: 6520400 | N19: 8550000 | O19: 4180000 | P19: 11532800 | Q19: 9600000 | R19: 9263900 | T19: =+MIN(J19,L19,M19,N19,P19,Q19,R19) -> 6520400 | U19: =+MAX(J19:R19) -> 18688032 | V19: =+ROUND(AVERAGE(J19,L19,M19,N19,P19,Q19,R19),2) -> 9474765.3 | W19: =+ROUND(AVERAGE(T19,V19),2) -> 7997582.6
A20: Subtotal B — Hardware de Salas (pago contra entrega) | G20: =SUM(G14:G19) -> 2.311225e+09
A22: TOTAL DOMINIO 3 — VIDEOCONFERENCIA | G22: =G11+G20 -> 5.2374834e+10

Sheet D4. Cableado
A1: DOMINIO 4 — CABLEADO ESTRUCTURADO (BOLSA DE PUNTOS CATEGORÍA 6A BLINDADO)
A2: Anexo Técnico 4 — Modalidad bolsa de monto agotable / Pago por punto efectivamente ejecutado
A4: Ítem | B4: Servicio / Componente | C4: Unidad | D4: Cantidad | E4: Tarifa unitaria mensual (COP) | F4: Meses | G4: Costo total 36 meses (COP) | H4: Observaciones | J4: WEXLER S.A.S. | K4: COLOMBIA TELECOMUNICACIONES S.A. ESP BIC | L4: SONDA DE COLOMBIA S.A. | M4: COMUNICACION CELULAR S A COMCEL S A | N4: GROW DATA S.A.S | O4: MEDIA COMMERCE S.A.S. | P4: TESERACT S.A.S. | Q4: YEAPDATA S.A.S. | R4: S3 SIMPLE SMART SPEEDY S.A.S. | T4: COIZACIÓN MÁS BAJA | U4: COTIZACIÓN MÁS ALTA | V4: PROMEDIO | W4: MEDIA ARITMÉTICA BAJA
A5: A. BOLSA DE PUNTOS DE CABLEADO (PAGO CONTRA EJECUCIÓN)
A6: 1 | B6: Punto completo de datos Cat 6A blindado (incluye salida datos + toma regulada + toma normal) | C6: Punto | D6: ='1. Parámetros'!$B$24 -> 6000 | E6: 1596689.5 | F6: 1 | G6: =ROUND(D6*E6*F6,2) -> 9580137180 | H6: Bolsa - 6.000 puntos máximos | J6: 1447546.1 | K6: 2050272.6 | L6: 1485476.6 | M6: 4092614.4 | N6: 5250000 | O6: 1406000 | P6: 3822772.3 | Q6: 3224362.8 | R6: 2547600 | T6: =+MIN(J6:R6) -> 1406000 | U6: =+MAX(J6:R6) -> 5250000 | V6: =+ROUND(AVERAGE(J6,K6,L6,O6,R6),2) -> 1787379.1 | W6: =+ROUND(AVERAGE(T6,V6),2) -> 1596689.5
A7: 2 | B7: Reubicación de punto lógico + eléctrico (cumple condiciones técnicas sin empalmes) | C7: Punto | D7: ='1. Parámetros'!$B$25 -> 1000 | E7: 686321.7 | F7: 1 | G7: =ROUND(D7*E7*F7,2) -> 686321700 | H7: Bolsa - 1.000 puntos máximos | J7: 542829.79 | K7: 603021.36 | L7: 655357.33 | M7: 1390207 | N7: 1877000 | O7: 646000 | P7: 1324006.2 | Q7: 3517486.8 | R7: 984400 | T7: =+MIN(J7:R7) -> 542829.79 | U7: =+MAX(J7:R7) -> 3517486.8 | V7: =+ROUND(AVERAGE(J7,K7,L7,O7,R7),2) -> 686321.7 | W7: =+ROUND(AVERAGE(T7,V7),2) -> 614575.75
A8: 3 | B8: Punto eléctrico regulado (cuando se requiere solo toma) | C8: Punto | D8: 800 | E8: 451826.73 | F8: 1 | G8: =ROUND(D8*E8*F8,2) -> 361461384 | H8: Bolsa según necesidad - sin contar | J8: 422200.94 | K8: 434175.38 | L8: 655357.33 | M8: 1111202.4 | N8: 1350000 | O8: 342000 | P8: 1043525.3 | Q8: 1020000 | R8: 405400 | T8: =+MIN(J8:R8) -> 342000 | U8: =+MAX(J8:R8) -> 1350000 | V8: =+ROUND(AVERAGE(J8,K8,L8,O8,R8),2) -> 451826.73 | W8: =+ROUND(AVERAGE(T8,V8),2) -> 396913.37
A9: 4 | B9: Punto eléctrico normal | C9: Punto | D9: 500 | E9: 295784.66 | F9: 1 | G9: =ROUND(D9*E9*F9,2) -> 147892330 | H9: Bolsa según necesidad - sin contar | J9: 301572.1 | K9: 289450.25 | L9: 337316.27 | M9: 1089456.2 | N9: 1288000 | O9: 144400 | P9: 1008416.9 | Q9: 660000 | R9: 254800 | T9: =+MIN(J9:R9) -> 144400 | U9: =+MAX(J9:R9) -> 1288000 | V9: =+ROUND(AVERAGE(J9,K9,L9,R9),2) -> 295784.66 | W9: =+ROUND(AVERAGE(T9,V9),2) -> 220092.33
A10: 5 | B10: Backbone fibra óptica multimodo OM4 12 hilos por enlace | C10: Enlace | D10: 120 | E10: 8709435.3 | F10: 1 | G10: =ROUND(D10*E10*F10,2) -> 1.0451322e+09 | H10: Interconexión entre racks (cuando aplica) | J10: 4222009.5 | K10: 8442299 | L10: 10859940 | M10: 14274135 | N10: 17300000 | O10: 4940000 | P10: 13205998 | Q10: 5400000 | R10: 13895800 | T10: =+MIN(J10:R10) -> 4222009.5 | U10: =+MAX(J10:R10) -> 17300000 | V10: =+ROUND(AVERAGE(J10,K10,L10,O10,P10,Q10,R10),2) -> 8709435.3 | W10: =+ROUND(AVERAGE(T10,V10),2) -> 6465722.4
A11: 6 | B11: Suministro e instalación de gabinete/rack de comunicaciones | C11: Unidad | D11: 80 | E11: 6542972.1 | F11: 1 | G11: =ROUND(D11*E11*F11,2) -> 5.2343777e+08 | H11: Bolsa de gabinetes - según diseño | J11: 5428297.9 | K11: 2894502.5 | L11: 8632260 | M11: 16090096 | N11: 19000000 | O11: 4180000 | P11: 14965894 | Q11: 17587436 | R11: 11579800 | T11: =+MIN(J11:R11) -> 2894502.5 | U11: =+MAX(J11:R11) -> 19000000 | V11: =+ROUND(AVERAGE(J11,K11,L11,O11,R11),2) -> 6542972.1 | W11: =+ROUND(AVERAGE(T11,V11),2) -> 4718737.3
A12: 7 | B12: Sistema de puesta a tierra (TGB/TMGB + medición + caja protección) | C12: Sede | D12: 150 | E12: 4365226.5 | F12: 1 | G12: =ROUND(D12*E12*F12,2) -> 654783972 | H12: Sedes que no cuenten con PAT | J12: 3618865.2 | K12: 6030213.6 | L12: 5012280 | M12: 8945519.8 | N12: 10723000 | O12: 1900000 | P12: 8147322.1 | Q12: 3840000 | R12: 5790000 | T12: =+MIN(J12:R12) -> 1900000 | U12: =+MAX(J12:R12) -> 10723000 | V12: =+ROUND(AVERAGE(J12,K12,L12,O12,Q12,R12),2) -> 4365226.5 | W12: =+ROUND(AVERAGE(T12,V12),2) -> 3132613.2
A13: 8 | B13: Visita Site Survey por sede (dimensionamiento previo) | C13: Sede | D13: 250 | E13: 667843.53 | F13: 1 | G13: =ROUND(D13*E13*F13,2) -> 1.6696088e+08 | H13: Previa a intervención | J13: 603144.21 | K13: 844229.9 | L13: 8040532.5 | M13: 5358599.4 | N13: 6251000 | O13: 684000 | P13: 5030693 | Q13: 540000 | R13: 2316000 | T13: =+MIN(J13:R13) -> 540000 | U13: =+MAX(J13:R13) -> 8040532.5 | V13: =+ROUND(AVERAGE(J13,K13,O13,Q13),2) -> 667843.53 | W13: =+ROUND(AVERAGE(T13,V13),2) -> 603921.77
A14: Subtotal A — Bolsa de Puntos y Componentes | G14: =SUM(G6:G13) -> 1.3166127e+10
A16: B. MANTENIMIENTO Y ATENCIÓN POR DEMANDA
A17: 1 | B17: Atención de incidentes y requerimientos en cableado (bolsa mensual) | C17: Servicio-mes | D17: 1 | E17: 14915385 | F17: 36 | G17: =ROUND(D17*E17*F17,2) -> 5.3695385e+08 | H17: Soporte correctivo - 36 meses | J17: 54282979 | K17: 28945025 | L17: 17403750 | M17: 17253600 | N17: 20300000 | O17: 11400000 | P17: 15282242 | Q17: 42000000 | R17: 57898900 | T17: =+MIN(J17:R17) -> 11400000 | U17: =+MAX(J17:R17) -> 57898900 | V17: =+ROUND(AVERAGE(K17,L17,M17,N17,O17,P17),2) -> 18430770 | W17: =+ROUND(AVERAGE(T17,V17),2) -> 14915385
A18: 2 | B18: Certificación y pruebas de desempeño post-instalación (por sede) | C18: Certificación | D18: 250 | E18: 413516.38 | F18: 1 | G18: =ROUND(D18*E18*F18,2) -> 103379095 | H18: Una por cada sede intervenida | J18: 217131.91 | K18: 1085438.4 | L18: 1194593.4 | M18: 7328998.6 | N18: 8750000 | O18: 342000 | P18: 6756934.2 | Q18: 216000 | R18: 3474000 | T18: =+MIN(J18:R18) -> 216000 | U18: =+MAX(J18:R18) -> 8750000 | V18: =+ROUND(AVERAGE(J18,K18,L18,O18,Q18),2) -> 611032.75 | W18: =+ROUND(AVERAGE(T18,V18),2) -> 413516.38
A19: Subtotal B — Mantenimiento y atención por demanda | G19: =SUM(G17:G18) -> 6.4033295e+08
A21: TOTAL DOMINIO 4 — CABLEADO ESTRUCTURADO | G21: =G14+G19 -> 1.380646e+10

Sheet P6. Perfiles
A1: ANEXO 6 — PERFILES PROFESIONALES DEL PROVEEDOR (36 MESES)
A2: Personal mínimo del contratista para la operación de los 5 dominios — Roles P1 a P7
A4: Ítem | B4: Perfil profesional | C4: Categoría (P1-P7) | D4: Cant. | E4: Dedic. (%) | F4: Salario base mensual (COP) | G4: Factor multip. | H4: Costo mensual total (COP) | I4: Meses | J4: Total perfil 36 meses (COP) | L4: WEXLER S.A.S. | M4: COLOMBIA TELECOMUNICACIONES S.A. ESP BIC | N4: SONDA DE COLOMBIA S.A. | O4: COMUNICACION CELULAR S A COMCEL S A | P4: GROW DATA S.A.S | Q4: MEDIA COMMERCE S.A.S. | R4: TESERACT S.A.S. | S4: YEAPDATA S.A.S. | T4: S3 SIMPLE SMART SPEEDY S.A.S. | V4: COIZACIÓN MÁS BAJA | W4: COTIZACIÓN MÁS ALTA | X4: PROMEDIO | Y4: MEDIA ARITMÉTICA BAJA
A5: P1 — ROLES ESTRATÉGICOS TRANSVERSALES
A6: 1 | B6: Gerente de Proyecto Presencial (PMP) — Único punto de contacto | C6: P1 | D6: 1 | E6: 1 | F6: 26043339 | G6: ='1. Parámetros'!$B$28 -> 1.85 | H6: =D6*E6*F6*G6 -> 48180177 | I6: ='1. Parámetros'!$B$4 -> 36 | J6: =ROUND(H6*I6,2) -> 1.7344864e+09 | L6: 30157210 | M6: 18486486 | N6: 30362998 | O6: 35275000 | P6: 30750000 | Q6: 20460000 | R6: 54487040 | S6: 17752982 | T6: 16383900 | V6: =+MIN(L6:T6) -> 16383900 | W6: =+MAX(L6:T6) -> 54487040 | X6: =+ROUND(AVERAGE(L6,M6,N6,P6,Q6),2) -> 26043339 | Y6: =+ROUND(AVERAGE(X6,V6),2) -> 21213619
A7: 2 | B7: Director Técnico (TOGAF + ITIL Strategic Leader) | C7: P1 | D7: 1 | E7: 1 | F7: 21279618 | G7: ='1. Parámetros'!$B$28 -> 1.85 | H7: =D7*E7*F7*G7 -> 39367293 | I7: ='1. Parámetros'!$B$4 -> 36 | J7: =ROUND(H7*I7,2) -> 1.4172225e+09 | L7: 33776076 | M7: 14594595 | N7: 25319418 | O7: 32300000 | P7: 33750000 | Q7: 20460000 | R7: 48720640 | S7: 22182352 | T7: 18828600 | V7: =+MIN(L7:T7) -> 14594595 | W7: =+MAX(L7:T7) -> 48720640 | X7: =+ROUND(AVERAGE(L7,N7,O7,P7,Q7,S7),2) -> 27964641 | Y7: =+ROUND(AVERAGE(X7,V7),2) -> 21279618
A8: 3 | B8: Jefe de Servicios (ITIL v4 + PMI) | C8: P1 | D8: 1 | E8: 1 | F8: 18514730 | G8: ='1. Parámetros'!$B$28 -> 1.85 | H8: =D8*E8*F8*G8 -> 34252251 | I8: ='1. Parámetros'!$B$4 -> 36 | J8: =ROUND(H8*I8,2) -> 1.233081e+09 | L8: 26538345 | M8: 13486486 | N8: 23056894 | O8: 19975000 | P8: 22500000 | Q8: 17670000 | R8: 30464000 | S8: 14400000 | T8: 11562900 | V8: =+MIN(L8:T8) -> 11562900 | W8: =+MAX(L8:T8) -> 30464000 | X8: =+ROUND(AVERAGE(M8,N8,O8,P8,Q8,S8),2) -> 18514730 | Y8: =+ROUND(AVERAGE(X8,V8),2) -> 15038815
A9: 4 | B9: Gestor de Transición (PMP + ITIL Specialist) — Solo M1-M10 | C9: P1 | D9: 1 | E9: 1 | F9: 16791671 | G9: ='1. Parámetros'!$B$28 -> 1.85 | H9: =D9*E9*F9*G9 -> 31064591 | I9: ='1. Parámetros'!$B$27 -> 10 | J9: =ROUND(H9*I9,2) -> 3.1064591e+08 | L9: 24125768 | M9: 8432432.4 | N9: 21109225 | O9: 16575000 | P9: 21000000 | Q9: 16740000 | R9: 26242560 | S9: 16200000 | T9: 9125800 | V9: =+MIN(L9:T9) -> 8432432.4 | W9: =+MAX(L9:T9) -> 26242560 | X9: =+ROUND(AVERAGE(N9,O9,P9,Q9,S9,T9),2) -> 16791671 | Y9: =+ROUND(AVERAGE(X9,V9),2) -> 12612052
A10: P2 — PERFILES TÉCNICOS DE CONECTIVIDAD
A11: 5 | B11: Ingeniero Residente Bogotá (turno 1) — 5x12 | C11: P2 | D11: 1 | E11: 1 | F11: 11015995 | G11: ='1. Parámetros'!$B$28 -> 1.85 | H11: =D11*E11*F11*G11 -> 20379590 | I11: ='1. Parámetros'!$B$4 -> 36 | J11: =ROUND(H11*I11,2) -> 7.3366525e+08 | L11: 10856596 | M11: 10378378 | N11: 20661722 | O11: 11475000 | P11: 14000000 | Q11: 8370000 | R11: 18844160 | S11: 17605034 | T11: 7372100 | V11: =+MIN(L11:T11) -> 7372100 | W11: =+MAX(L11:T11) -> 20661722 | X11: =+ROUND(AVERAGE(L11,M11,O11,P11,Q11),2) -> 11015995 | Y11: =+ROUND(AVERAGE(X11,V11),2) -> 9194047.4
A12: 6 | B12: Ingeniero Residente Bogotá (turno 2) — 5x12 | C12: P2 | D12: 1 | E12: 1 | F12: 11015995 | G12: ='1. Parámetros'!$B$28 -> 1.85 | H12: =D12*E12*F12*G12 -> 20379590 | I12: ='1. Parámetros'!$B$4 -> 36 | J12: =ROUND(H12*I12,2) -> 7.3366525e+08 | L12: 10856596 | M12: 10378378 | N12: 20661722 | O12: 11475000 | P12: 14000000 | Q12: 8370000 | R12: 17429760 | S12: 17605034 | T12: 7372100 | V12: =+MIN(L12:T12) -> 7372100 | W12: =+MAX(L12:T12) -> 20661722 | X12: =+ROUND(AVERAGE(L12,M12,O12,P12,Q12),2) -> 11015995 | Y12: =+ROUND(AVERAGE(X12,V12),2) -> 9194047.4
A13: 7 | B13: Ingeniero Residente Cali — 5x8 | C13: P2 | D13: 1 | E13: 1 | F13: 10725366 | G13: ='1. Parámetros'!$B$28 -> 1.85 | H13: =D13*E13*F13*G13 -> 19841927 | I13: ='1. Parámetros'!$B$4 -> 36 | J13: =ROUND(H13*I13,2) -> 7.1430937e+08 | L13: 10253452 | M13: 10378378 | N13: 19122596 | O13: 10625000 | P13: 14000000 | Q13: 8370000 | R13: 15895680 | S13: 17605034 | T13: 5899200 | V13: =+MIN(L13:T13) -> 5899200 | W13: =+MAX(L13:T13) -> 19122596 | X13: =+ROUND(AVERAGE(L13,M13,O13,P13,Q13),2) -> 10725366 | Y13: =+ROUND(AVERAGE(X13,V13),2) -> 8312283
A14: 8 | B14: Especialista en Conectividad WAN/SD-WAN (CCNP/JNCIP) | C14: P2 | D14: 2 | E14: 1 | F14: 12818768 | G14: ='1. Parámetros'!$B$28 -> 1.85 | H14: =D14*E14*F14*G14 -> 47429441 | I14: ='1. Parámetros'!$B$4 -> 36 | J14: =ROUND(H14*I14,2) -> 1.7074599e+09 | L14: 14475461 | M14: 10378378 | N14: 21489147 | O14: 20400000 | P14: 15750000 | Q14: 12090000 | R14: 31878400 | S14: 11400000 | T14: 7592300 | V14: =+MIN(L14:T14) -> 7592300 | W14: =+MAX(L14:T14) -> 31878400 | X14: =+ROUND(AVERAGE(L14,M14,P14,Q14,S14),2) -> 12818768 | Y14: =+ROUND(AVERAGE(X14,V14),2) -> 10205534
A15: 9 | B15: Especialista SD-WAN avanzado (orquestador, ADVPN, QoS) | C15: P2 | D15: 1 | E15: 1 | F15: 14197283 | G15: ='1. Parámetros'!$B$28 -> 1.85 | H15: =D15*E15*F15*G15 -> 26264974 | I15: ='1. Parámetros'!$B$4 -> 36 | J15: =ROUND(H15*I15,2) -> 9.4553906e+08 | L15: 16888038 | M15: 10378378 | N15: 22989323 | O15: 19975000 | P15: 17500000 | Q15: 13020000 | R15: 31976320 | S15: 13200000 | T15: 8844900 | V15: =+MIN(L15:T15) -> 8844900 | W15: =+MAX(L15:T15) -> 31976320 | X15: =+ROUND(AVERAGE(L15,M15,P15,Q15,S15),2) -> 14197283 | Y15: =+ROUND(AVERAGE(X15,V15),2) -> 11521092
A16: 10 | B16: Ingeniero NOC 7x24 (turnos rotativos) | C16: P2 | D16: 4 | E16: 1 | F16: 7940668.7 | G16: ='1. Parámetros'!$B$28 -> 1.85 | H16: =D16*E16*F16*G16 -> 58760948 | I16: ='1. Parámetros'!$B$4 -> 36 | J16: =ROUND(H16*I16,2) -> 2.1153941e+09 | L16: 8444018.9 | M16: 6324324.3 | N16: 13260941 | O16: 10625000 | P16: 14000000 | Q16: 6510000 | R16: 17201280 | S16: 7800000 | T16: 3796200 | V16: =+MIN(L16:T16) -> 3796200 | W16: =+MAX(L16:T16) -> 17201280 | X16: =+ROUND(AVERAGE(L16,M16,O16,Q16,S16),2) -> 7940668.7 | Y16: =+ROUND(AVERAGE(X16,V16),2) -> 5868434.3
A17: P3 — PERFILES TÉCNICOS DE SEGURIDAD (SOC + SASE + DLP + NAC + PAM)
A18: 11 | B18: Gerente de Seguridad (CISSP + ISO 27001 Lead Auditor) | C18: P3 | D18: 1 | E18: 1 | F18: 19442730 | G18: ='1. Parámetros'!$B$28 -> 1.85 | H18: =D18*E18*F18*G18 -> 35969050 | I18: ='1. Parámetros'!$B$4 -> 36 | J18: =ROUND(H18*I18,2) -> 1.2948858e+09 | L18: 31363499 | M18: 15175676 | N18: 33573383 | O18: 47000000 | P18: 35500000 | Q18: 20460000 | R18: 56891520 | S18: 19800000 | T18: 12906700 | V18: =+MIN(L18:T18) -> 12906700 | W18: =+MAX(L18:T18) -> 56891520 | X18: =+ROUND(AVERAGE(L18,M18,N18,P18,Q18,S18),2) -> 25978760 | Y18: =+ROUND(AVERAGE(X18,V18),2) -> 19442730
A19: 12 | B19: Coordinador SOC (GIAC GSOC) | C19: P3 | D19: 1 | E19: 1 | F19: 13633772 | G19: ='1. Parámetros'!$B$28 -> 1.85 | H19: =D19*E19*F19*G19 -> 25222479 | I19: ='1. Parámetros'!$B$4 -> 36 | J19: =ROUND(H19*I19,2) -> 9.0800924e+08 | L19: 21713191 | M19: 10378378 | N19: 18025984 | O19: 26500000 | P19: 27750000 | Q19: 16740000 | R19: 35914880 | S19: 13800000 | T19: 9224500 | V19: =+MIN(L19:T19) -> 9224500 | W19: =+MAX(L19:T19) -> 35914880 | X19: =+ROUND(AVERAGE(M19,N19,Q19,S19,T19),2) -> 13633772 | Y19: =+ROUND(AVERAGE(X19,V19),2) -> 11429136
A20: 13 | B20: Analista SOC N1 — Turnos 7x24 | C20: P3 | D20: 6 | E20: 1 | F20: 6431403.6 | G20: ='1. Parámetros'!$B$28 -> 1.85 | H20: =D20*E20*F20*G20 -> 71388580 | I20: ='1. Parámetros'!$B$4 -> 36 | J20: =ROUND(H20*I20,2) -> 2.5699889e+09 | L20: 7840874.7 | M20: 4743243.2 | N20: 23741384 | O20: 18500000 | P20: 8750000 | Q20: 6975000 | R20: 23761920 | S20: 6600000 | T20: 5997900 | V20: =+MIN(L20:T20) -> 4743243.2 | W20: =+MAX(L20:T20) -> 23761920 | X20: =+ROUND(AVERAGE(L20,M20,Q20,S20,T20),2) -> 6431403.6 | Y20: =+ROUND(AVERAGE(X20,V20),2) -> 5587323.4
A21: 14 | B21: Analista SOC N2 — Threat hunting / casos complejos | C21: P3 | D21: 4 | E21: 1 | F21: 8657452.8 | G21: ='1. Parámetros'!$B$28 -> 1.85 | H21: =D21*E21*F21*G21 -> 64065151 | I21: ='1. Parámetros'!$B$4 -> 36 | J21: =ROUND(H21*I21,2) -> 2.3063454e+09 | L21: 11459740 | M21: 6324324.3 | N21: 31738074 | O21: 23000000 | P21: 14000000 | Q21: 8835000 | R21: 27559040 | S21: 9000000 | T21: 7668200 | V21: =+MIN(L21:T21) -> 6324324.3 | W21: =+MAX(L21:T21) -> 31738074 | X21: =+ROUND(AVERAGE(L21,M21,Q21,S21,T21),2) -> 8657452.8 | Y21: =+ROUND(AVERAGE(X21,V21),2) -> 7490888.6
A22: 15 | B22: Analista SOC N3 — Incident response / forensia | C22: P3 | D22: 2 | E22: 1 | F22: 12000447 | G22: ='1. Parámetros'!$B$28 -> 1.85 | H22: =D22*E22*F22*G22 -> 44401654 | I22: ='1. Parámetros'!$B$4 -> 36 | J22: =ROUND(H22*I22,2) -> 1.5984595e+09 | L22: 15681749 | M22: 8432432.4 | N22: 24737028 | O22: 32000000 | P22: 15750000 | Q22: 11020500 | R22: 43694080 | S22: 11400000 | T22: 9718000 | V22: =+MIN(L22:T22) -> 8432432.4 | W22: =+MAX(L22:T22) -> 43694080 | X22: =+ROUND(AVERAGE(L22,M22,P22,Q22,S22,T22),2) -> 12000447 | Y22: =+ROUND(AVERAGE(X22,V22),2) -> 10216440
A23: 16 | B23: Especialista SASE/SSE (administración plataforma) | C23: P3 | D23: 1 | E23: 1 | F23: 12466469 | G23: ='1. Parámetros'!$B$28 -> 1.85 | H23: =D23*E23*F23*G23 -> 23062968 | I23: ='1. Parámetros'!$B$4 -> 36 | J23: =ROUND(H23*I23,2) -> 8.3026686e+08 | L23: 16888038 | M23: 10378378 | N23: 31738074 | O23: 21500000 | P23: 15750000 | Q23: 12555000 | R23: 27123840 | S23: 10800000 | T23: 8427400 | V23: =+MIN(L23:T23) -> 8427400 | W23: =+MAX(L23:T23) -> 31738074 | X23: =+ROUND(AVERAGE(L23,M23,P23,Q23,S23,T23),2) -> 12466469 | Y23: =+ROUND(AVERAGE(X23,V23),2) -> 10446935
A24: 17 | B24: Operadores de seguridad (NGFW,WAF,DDoS,Antimalware) | C24: P3 | D24: 1 | E24: 1 | F24: 8739088.3 | G24: ='1. Parámetros'!$B$28 -> 1.85 | H24: =D24*E24*F24*G24 -> 16167313 | I24: ='1. Parámetros'!$B$4 -> 36 | J24: =ROUND(H24*I24,2) -> 5.8202328e+08 | L24: 10253452 | M24: 10378378 | N24: 24503660 | O24: 17500000 | P24: 12000000 | Q24: 7440000 | R24: 21760000 | S24: 7200000 | T24: 5162700 | V24: =+MIN(L24:T24) -> 5162700 | W24: =+MAX(L24:T24) -> 24503660 | X24: =+ROUND(AVERAGE(L24,M24,P24,Q24,S24,T24),2) -> 8739088.3 | Y24: =+ROUND(AVERAGE(X24,V24),2) -> 6950894.1
A25: 18 | B25: Especialista DevSecOps (SOAR, CI/CD) | C25: P3 | D25: 1 | E25: 1 | F25: 11893130 | G25: ='1. Parámetros'!$B$28 -> 1.85 | H25: =D25*E25*F25*G25 -> 22002291 | I25: ='1. Parámetros'!$B$4 -> 36 | J25: =ROUND(H25*I25,2) -> 7.9208246e+08 | L25: 16284894 | M25: 13486486 | N25: 24270292 | O25: 24500000 | P25: 10000000 | Q25: 11160000 | R25: 30464000 | S25: 12000000 | T25: 8427400 | V25: =+MIN(L25:T25) -> 8427400 | W25: =+MAX(L25:T25) -> 30464000 | X25: =+ROUND(AVERAGE(L25,M25,P25,Q25,S25,T25),2) -> 11893130 | Y25: =+ROUND(AVERAGE(X25,V25),2) -> 10160265
A26: 19 | B26: Especialista EDR/XDR (endpoint security) | C26: P3 | D26: 1 | E26: 1 | F26: 11366173 | G26: ='1. Parámetros'!$B$28 -> 1.85 | H26: =D26*E26*F26*G26 -> 21027420 | I26: ='1. Parámetros'!$B$4 -> 36 | J26: =ROUND(H26*I26,2) -> 7.5698713e+08 | L26: 14475461 | M26: 10378378 | N26: 24737028 | O26: 19200000 | P26: 14875000 | Q26: 11625000 | R26: 23326720 | S26: 10200000 | T26: 6643200 | V26: =+MIN(L26:T26) -> 6643200 | W26: =+MAX(L26:T26) -> 24737028 | X26: =+ROUND(AVERAGE(L26,M26,P26,Q26,S26,T26),2) -> 11366173 | Y26: =+ROUND(AVERAGE(X26,V26),2) -> 9004686.6
A27: 20 | B27: Especialista DLP (M365 + endpoint + SSE) | C27: P3 | D27: 1 | E27: 1 | F27: 11929501 | G27: ='1. Parámetros'!$B$28 -> 1.85 | H27: =D27*E27*F27*G27 -> 22069576 | I27: ='1. Parámetros'!$B$4 -> 36 | J27: =ROUND(H27*I27,2) -> 7.9450474e+08 | L27: 13872317 | M27: 13486486 | N27: 24036924 | O27: 19800000 | P27: 15750000 | Q27: 11625000 | R27: 26188160 | S27: 10200000 | T27: 6643200 | V27: =+MIN(L27:T27) -> 6643200 | W27: =+MAX(L27:T27) -> 26188160 | X27: =+ROUND(AVERAGE(L27,M27,P27,Q27,S27,T27),2) -> 11929501 | Y27: =+ROUND(AVERAGE(X27,V27),2) -> 9286350.3
A28: 21 | B28: Especialista NAC (control de acceso a red) | C28: P3 | D28: 1 | E28: 1 | F28: 11074292 | G28: ='1. Parámetros'!$B$28 -> 1.85 | H28: =D28*E28*F28*G28 -> 20487440 | I28: ='1. Parámetros'!$B$4 -> 36 | J28: =ROUND(H28*I28,2) -> 7.3754783e+08 | L28: 13269173 | M28: 10378378 | N28: 24970396 | O28: 19500000 | P28: 14000000 | Q28: 12555000 | R28: 25959680 | S28: 9600000 | T28: 6643200 | V28: =+MIN(L28:T28) -> 6643200 | W28: =+MAX(L28:T28) -> 25959680 | X28: =+ROUND(AVERAGE(L28,M28,P28,Q28,S28,T28),2) -> 11074292 | Y28: =+ROUND(AVERAGE(X28,V28),2) -> 8858745.9
A29: 22 | B29: Especialista PAM (Privileged Access Management) | C29: P3 | D29: 1 | E29: 1 | F29: 11482864 | G29: ='1. Parámetros'!$B$28 -> 1.85 | H29: =D29*E29*F29*G29 -> 21243298 | I29: ='1. Parámetros'!$B$4 -> 36 | J29: =ROUND(H29*I29,2) -> 7.6475873e+08 | L29: 15078605 | M29: 10378378 | N29: 24737028 | O29: 21000000 | P29: 14000000 | Q29: 11997000 | R29: 27624320 | S29: 10800000 | T29: 6643200 | V29: =+MIN(L29:T29) -> 6643200 | W29: =+MAX(L29:T29) -> 27624320 | X29: =+ROUND(AVERAGE(L29,M29,P29,Q29,S29,T29),2) -> 11482864 | Y29: =+ROUND(AVERAGE(X29,V29),2) -> 9063031.9
A30: 23 | B30: Pentester / Ethical Hacker (OSCP) | C30: P3 | D30: 1 | E30: 0.5 | F30: 14850234 | G30: ='1. Parámetros'!$B$28 -> 1.85 | H30: =D30*E30*F30*G30 -> 13736466 | I30: ='1. Parámetros'!$B$4 -> 36 | J30: =ROUND(H30*I30,2) -> 4.9451279e+08 | L30: 18094326 | M30: 10378378 | N30: 24036924 | O30: 18500000 | P30: 26250000 | Q30: 17205000 | R30: 26220800 | S30: 16800000 | T30: 8123700 | V30: =+MIN(L30:T30) -> 8123700 | W30: =+MAX(L30:T30) -> 26250000 | X30: =+ROUND(AVERAGE(L30,M30,O30,Q30,S30,T30),2) -> 14850234 | Y30: =+ROUND(AVERAGE(X30,V30),2) -> 11486967
A31: P4 — PERFILES DE SERVICIOS, MESA DE AYUDA Y OBSERVABILIDAD
A32: 24 | B32: Coordinador de Agentes (Mesa de Ayuda) | C32: P4 | D32: 1 | E32: 1 | F32: 8321064 | G32: ='1. Parámetros'!$B$28 -> 1.85 | H32: =D32*E32*F32*G32 -> 15393968 | I32: ='1. Parámetros'!$B$4 -> 36 | J32: =ROUND(H32*I32,2) -> 5.5418286e+08 | L32: 10856596 | M32: 8324324.3 | N32: 20087285 | O32: 13005000 | P32: 14000000 | Q32: 7905000 | R32: 21607680 | S32: 8400000 | T32: 6119400 | V32: =+MIN(L32:T32) -> 6119400 | W32: =+MAX(L32:T32) -> 21607680 | X32: =+ROUND(AVERAGE(L32,M32,Q32,S32,T32),2) -> 8321064 | Y32: =+ROUND(AVERAGE(X32,V32),2) -> 7220232
A33: 25 | B33: Agentes Mesa de Ayuda N1 (atención remota) | C33: P4 | D33: 12 | E33: 1 | F33: 4744151.6 | G33: ='1. Parámetros'!$B$28 -> 1.85 | H33: =D33*E33*F33*G33 -> 1.0532017e+08 | I33: ='1. Parámetros'!$B$4 -> 36 | J33: =ROUND(H33*I33,2) -> 3.791526e+09 | L33: 3860122.9 | M33: 3635135.1 | N33: 13344154 | O33: 8925000 | P33: 7875000 | Q33: 4510500 | R33: 15112320 | S33: 3840000 | T33: 2718100 | V33: =+MIN(L33:T33) -> 2718100 | W33: =+MAX(L33:T33) -> 15112320 | X33: =+ROUND(AVERAGE(L33,M33,P33,Q33,S33),2) -> 4744151.6 | Y33: =+ROUND(AVERAGE(X33,V33),2) -> 3731125.8
A34: 26 | B34: Agentes Mesa de Ayuda N2 (escalamiento) | C34: P4 | D34: 6 | E34: 1 | F34: 5880597.4 | G34: ='1. Parámetros'!$B$28 -> 1.85 | H34: =D34*E34*F34*G34 -> 65274631 | I34: ='1. Parámetros'!$B$4 -> 36 | J34: =ROUND(H34*I34,2) -> 2.3498867e+09 | L34: 5428297.9 | M34: 4689189.2 | N34: 18594862 | O34: 10625000 | P34: 7875000 | Q34: 6370500 | R34: 17538560 | S34: 5040000 | T34: 3416600 | V34: =+MIN(L34:T34) -> 3416600 | W34: =+MAX(L34:T34) -> 18594862 | X34: =+ROUND(AVERAGE(L34,M34,P34,Q34,S34),2) -> 5880597.4 | Y34: =+ROUND(AVERAGE(X34,V34),2) -> 4648598.7
A35: 27 | B35: Técnicos de soporte en sitio (presencial sedes Bogotá) | C35: P4 | D35: 8 | E35: 1 | F35: 4901103.5 | G35: ='1. Parámetros'!$B$28 -> 1.85 | H35: =D35*E35*F35*G35 -> 72536332 | I35: ='1. Parámetros'!$B$4 -> 36 | J35: =ROUND(H35*I35,2) -> 2.611308e+09 | L35: 4583896 | M35: 2371621.6 | N35: 13946146 | O35: 8500000 | P35: 7875000 | Q35: 5115000 | R35: 13730560 | S35: 4560000 | T35: 3226700 | V35: =+MIN(L35:T35) -> 2371621.6 | W35: =+MAX(L35:T35) -> 13946146 | X35: =+ROUND(AVERAGE(L35,M35,P35,Q35,S35),2) -> 4901103.5 | Y35: =+ROUND(AVERAGE(X35,V35),2) -> 3636362.6
A36: 28 | B36: Especialista de Observabilidad (Splunk/Elastic/Dynatrace) | C36: P4 | D36: 1 | E36: 1 | F36: 11140348 | G36: ='1. Parámetros'!$B$28 -> 1.85 | H36: =D36*E36*F36*G36 -> 20609643 | I36: ='1. Parámetros'!$B$4 -> 36 | J36: =ROUND(H36*I36,2) -> 7.4194715e+08 | L36: 14475461 | M36: 8324324.3 | N36: 20460170 | O36: 16575000 | P36: 15750000 | Q36: 9300000 | R36: 28190080 | S36: 11400000 | T36: 7592300 | V36: =+MIN(L36:T36) -> 7592300 | W36: =+MAX(L36:T36) -> 28190080 | X36: =+ROUND(AVERAGE(L36,M36,P36,Q36,S36,T36),2) -> 11140348 | Y36: =+ROUND(AVERAGE(X36,V36),2) -> 9366323.8
A37: P5 — PERFILES TÉCNICOS DE VIDEOCONFERENCIA
A38: 29 | B38: Agentes de Videoconferencia (3 agentes) | C38: P5 | D38: 3 | E38: 1 | F38: 5776871.8 | G38: ='1. Parámetros'!$B$28 -> 1.85 | H38: =D38*E38*F38*G38 -> 32061638 | I38: ='1. Parámetros'!$B$4 -> 36 | J38: =ROUND(H38*I38,2) -> 1.154219e+09 | L38: 5428297.9 | M38: 4689189.2 | N38: 16838403 | O38: 10625000 | P38: 7875000 | Q38: 5115000 | R38: 16200320 | S38: 12323536 | T38: 3006600 | V38: =+MIN(L38:T38) -> 3006600 | W38: =+MAX(L38:T38) -> 16838403 | X38: =+ROUND(AVERAGE(L38,M38,P38,Q38),2) -> 5776871.8 | Y38: =+ROUND(AVERAGE(X38,V38),2) -> 4391735.9
A39: 30 | B39: Operador de Sala VC (CTS AVIXA) — Eventos críticos DJT | C39: P5 | D39: 2 | E39: 1 | F39: 6645943.9 | G39: ='1. Parámetros'!$B$28 -> 1.85 | H39: =D39*E39*F39*G39 -> 24589992 | I39: ='1. Parámetros'!$B$4 -> 36 | J39: =ROUND(H39*I39,2) -> 8.8523972e+08 | L39: 6634586.3 | M39: 4689189.2 | N39: 18230703 | O39: 8925000 | P39: 8750000 | Q39: 6510000 | R39: 14535680 | S39: 6600000 | T39: 3226700 | V39: =+MIN(L39:T39) -> 3226700 | W39: =+MAX(L39:T39) -> 18230703 | X39: =+ROUND(AVERAGE(L39,M39,P39,Q39),2) -> 6645943.9 | Y39: =+ROUND(AVERAGE(X39,V39),2) -> 4936321.9
A40: 31 | B40: Ingeniero de Plataforma UCaaS (Cisco/Teams/Zoom/Pexip) | C40: P5 | D40: 1 | E40: 1 | F40: 9885315.6 | G40: ='1. Parámetros'!$B$28 -> 1.85 | H40: =D40*E40*F40*G40 -> 18287834 | I40: ='1. Parámetros'!$B$4 -> 36 | J40: =ROUND(H40*I40,2) -> 6.5836202e+08 | L40: 12062884 | M40: 7378378.4 | N40: 26269129 | O40: 15300000 | P40: 17500000 | Q40: 9300000 | R40: 25296000 | S40: 10800000 | V40: =+MIN(L40:T40) -> 7378378.4 | W40: =+MAX(L40:T40) -> 26269129 | X40: =+ROUND(AVERAGE(L40,M40,Q40,S40,T40),2) -> 9885315.6 | Y40: =+ROUND(AVERAGE(X40,V40),2) -> 8631847
A41: P6 — PERFILES TÉCNICOS DE CABLEADO ESTRUCTURADO
...

Sheet GG. Gastos Generales
A1: GASTOS GENERALES, TRANSICIÓN Y ADMINISTRACIÓN DEL CONTRATO
A3: Ítem | B3: Concepto | C3: Unidad | D3: Cantidad | E3: Valor unitario (COP) | F3: Meses | G3: Costo total (COP) | I3: WEXLER S.A.S. | J3: COLOMBIA TELECOMUNICACIONES S.A. ESP BIC | K3: SONDA DE COLOMBIA S.A. | L3: COMUNICACION CELULAR S A COMCEL S A | M3: GROW DATA S.A.S | N3: MEDIA COMMERCE S.A.S. | O3: TESERACT S.A.S. | P3: YEAPDATA S.A.S. | Q3: S3 SIMPLE SMART SPEEDY S.A.S. | S3: COIZACIÓN MÁS BAJA | T3: COTIZACIÓN MÁS ALTA | U3: PROMEDIO | V3: MEDIA ARITMÉTICA BAJA
A4: A. PROTOCOLO DE TRANSICIÓN (M1-M10)
A5: 1 | B5: Plan Detallado de Transición (PDT) y documentación de plataforma actual | C5: Entregable | D5: 1 | E5: 98553853 | F5: 1 | G5: =ROUND(D5*E5*F5,2) -> 98553853 | I5: 96503073 | J5: 230000000 | K5: 14875000 | L5: 168000000 | M5: 345000000 | N5: 26600000 | O5: 600576000 | P5: 96000000 | Q5: 57898900 | S5: =+MIN(I5:Q5) -> 14875000 | T5: =+MAX(I5:Q5) -> 600576000 | U5: =+ROUND(AVERAGE(I5,J5,K5,L5,N5,P5,Q5),2) -> 98553853 | V5: =+ROUND(AVERAGE(S5,U5),2) -> 56714427
