Workbook

Sheet 0. Resumen Ejecutivo
A1: PRESTAR LOS SERVICIOS DE TELECOMUNICACIONES DE RED CORPORATIVA WAN-LAN, SEGURIDAD INFORMÁTICA Y VIDEOCONFERENCIA PARA LA FISCALÍA GENERAL DE LA NACIÓN
A2: Servicios Gestionados TIC Integrales — Fiscalía General de la Nación | 36 meses | 876 sedes | 5 dominios técnicos
A3: ANEXO 4. FORMATO DE OFERTA ECONÓMICA - CUADRO DE COSTOS CONSOLIDADO
A4: Ítem | B4: Componente | C4: Hoja de detalle | D4: Valor (COP) | E4: % Costo Directo
A5: D1 | B5: DOMINIO 1 — Conectividad WAN-LAN SD-WAN | C5: 'D1. Conectividad' | D5: ='D1. Conectividad'!G23 -> 3.0142861e+11 | E5: =D5/$D$11 -> 0.6121651
A6: D2 | B6: DOMINIO 2 — Seguridad Digital y Ciberseguridad | C6: 'D2. Seguridad' | D6: ='D2. Seguridad'!G30 -> 86261520000 | E6: =D6/$D$11 -> 0.17518672
A7: D3 | B7: DOMINIO 3 — Videoconferencia (UCaaS + Hardware) | C7: 'D3. Videoconferencia' | D7: ='D3. Videoconferencia'!G22 -> 30340948000 | E7: =D7/$D$11 -> 0.061618799
A8: D4 | B8: DOMINIO 4 — Cableado Estructurado (bolsa de puntos) | C8: 'D4. Cableado' | D8: ='D4. Cableado'!G21 -> 11306900000 | E8: =D8/$D$11 -> 0.022962948
A9: P6 | B9: ANEXO 6 — Perfiles Profesionales (36 meses) | C9: 'P6. Perfiles' | D9: ='P6. Perfiles'!J54 -> 53523722700 | E9: =D9/$D$11 -> 0.10870021
A10: GG | B10: Gastos Generales, Transición y Administración | C10: 'GG. Gastos Generales' | D10: ='GG. Gastos Generales'!G32 -> 9535880000 | E10: =D10/$D$11 -> 0.01936622
A11: TOTAL | D11: =SUM(D5:D10) -> 4.9239759e+11 | E11: 100.0%
A13: VALOR TOTAL ESTIMADO DEL CONTRATO ARCANUS 2026 (36 MESES, IVA INCLUIDO Y TODOS LOS COSTOS DIRECTOS E INDIRECTOS A QUE HAYA LUGAR) | D13: =+D11 -> 4.9239759e+11
A14: Valor mensual promedio (sobre 36 meses, IVA incluido) | D14: =D13/'1. Parámetros'!$B$4 -> 1.3677711e+10
A15: Costo promedio por sede (876 sedes, 36 meses) | D15: =D13/'1. Parámetros'!$B$5 -> 5.620977e+08
A17: OBSERVACIONES PARA EL ESTUDIO DEL SECTOR
A18: • Esta proyección de costos constituye una estimación referencial para el ESTUDIO DEL SECTOR conforme al Decreto 1600 de 2024. Los valores unitarios deben validarse con MÍNIMO DOS (2) cotizaciones formales y consultas en SECOP II.
A19: • La modalidad de selección es LICITACIÓN PÚBLICA con adjudicación a un único proponente (o proponente plural), conforme lo justifica la integralidad del proyecto y la responsabilidad extremo a extremo sobre los ANS.
A20: • La forma de pago combina TRES esquemas: (a) tarifa mensual por servicios recurrentes (conectividad, seguridad, UCaaS), (b) pago contra entrega de hardware (soluciones VC, kits LEO), (c) bolsa de monto agotable (cableado por punto ejecutado).
A21: • Los ANS extremadamente exigentes (99.99% disponibilidad, RTO 8 minutos) y la responsabilidad extremo a extremo justifican el factor multiplicador y los porcentajes de administración/utilidad aplicados.
A22: • El esquema de coexistencia operacional con el proveedor saliente (10 meses) genera sobrecostos específicos contemplados en la sección de Transición.
A23: • La liquidación de pagos estará sujeta a ajustes económicos y créditos de servicio por incumplimiento de ANS, conforme al Anexo 5 — Acuerdos de Niveles de Servicio.
A24: • El presente cuadro NO incluye la interventoría del contrato (proceso independiente bajo Concurso de Méritos — ver cuadro de costos separado).
A25: • En su cotización debe incluir IVA y todos los costos directos e indirectos a que haya lugar.
A26: IMPORTANTE: 1. El proponente en la estructuración de su oferta económica deberá presentar máximo DOS (2) decimales. 2, En el caso que se presenten más de DOS (2) decimales, se recomienda utilizar el método de redondeo estándar, esto es, si el tercer decimal es menor que CINCO (5), el segundo decimal se mantiene; si el tercer decimal es igual o mayor que CINCO (5), el segundo decimal se incrementa en uno. 3. En caso de presentar exclusión de algún impuesto, anexar la correspondiente justificación debidamente firmada por el Representante Legal. 4. No modificar ninguna especificación descrita en la necesidad. 5. Tener en cuenta las causales de rechazo establecidas en el Pliego de condiciones. 6. Debe ajustarse exactamente a lo solicitado en la Ficha Técnica. 7. Debe presentar oferta en formato EXCEL EDITABLE.
A27: Marque con una X la opción que corresponda
A28: PERSONA JURÍDICA
... A37: Fecha de Oferta:
A38: Validez de Oferta económica 90 días: | C38: SI ___ NO_____
A39: ¿Cumple con lo solicitado en le Ficha Técnica? | C39: SI ___ NO_____
A40: FIRMA DIGITAL

Sheet 1. Parámetros
A1: LICITACIÓN ARCANUS 2026 (FISCATEL) — PARÁMETROS Y SUPUESTOS
A3: Variable | B3: Valor | C3: Unidad | D3: Fuente / Justificación
A4: Plazo total del contrato | B4: 36 | C4: meses | D4: Anexo Técnico de Interventoría / Fase IV M13-M36
A5: Total de sedes a atender | B5: 876 | C5: sedes | D5: Anexo 1.1 Sedes (876 filas). NOTA: Anexo 2 S1.1.2 cita 877 y Anexo 7 cita 881 nodos - pendiente armonizar
A6: Sedes Cat 1 - Datacenters/Núcleo SD-WAN | B6: 2 | C6: nodos | D6: Bogotá Salitre + Cali Bunker (activo-activo)
A7: Sedes Cat 2 - Principales (capitales) | B7: 765 | C7: sedes | D7: AT1 Conectividad (matriz post-consolidación)
A8: Sedes Cat 3 - Intermedias (ciudades medianas) | B8: 86 | C8: sedes | D8: AT1 Conectividad
A9: Sedes Cat 4 - Remotas (LEO satelital) | B9: 25 | C9: sedes | D9: AT1 Conectividad - zonas sin fibra
A10: Sedes Cat 5 - Nubes públicas (canales) | B10: 4 | C10: canales | D10: Azure ExpressRoute + OCI FastConnect (2 c/u)
A11: Sedes Cat 6 - Canales complementarios | B11: 4 | C11: canales | D11: AT1 Conectividad Cat 6 - cantidad NO cuantificada en anexos (estimacion por confirmar)
A12: Usuarios SASE/SSE | B12: 30000 | C12: usuarios | D12: AT2 Seguridad - licenciamiento perimetral
A13: Endpoints con XDR/EDR | B13: 26000 | C13: endpoints | D13: AT2 Seguridad - estaciones de trabajo
A14: Servidores Antimalware | B14: 500 | C14: servidores | D14: AT2 Seguridad S10: 500 servidores aprox. (250 Linux / 250 Windows) [ajustado de 600]
A15: Activos monitoreados SOC | B15: 1500 | C15: activos | D15: AT2 Seguridad - monitoreo 24x7
... A35: Estudios formales de trafico (36 meses) | B35: 4 | C35: estudios | D35: AT1 C13.3: 1 linea base + 3 anuales [REFERENCIA: la hoja D1 item 6 usa 12 - ajuste pendiente de aprobacion]
A37: NOTAS METODOLÓGICAS
A38: 1. Los valores unitarios son referenciales de mercado para servicios gestionados TIC en Colombia 2026 — deben validarse con MÍNIMO DOS (2) cotizaciones formales según Decreto 1600 de 2024.
A39: 2. El factor multiplicador (1.85) aplica solo a perfiles profesionales y cubre prestaciones, parafiscales, dotación, capacitación, certificaciones, administración y utilidad del consultor.
A40: 3. Servicios recurrentes (conectividad, seguridad, plataforma UCaaS) se modelan como tarifa mensual × meses. Hardware (soluciones VC, kits LEO) se factura contra entrega.
A41: 4. Cableado se factura bajo modalidad BOLSA DE MONTO AGOTABLE: se paga por punto efectivamente instalado/reubicado.
A42: 5. Los costos de Cat 1 (datacenter) incluyen 2 canales Internet 5Gbps + 2 canales datos 5Gbps + 2 canales por nube pública.
A43: 6. Las cantidades estimadas para servicios por demanda (SASE, EDR, puntos) son MÁXIMOS referenciales, no obligaciones mínimas de consumo para la Entidad.
A44: 7. AJUSTES 31-07-2026 (solo hoja Parametros, validacion vs anexos): servidores 600->500 (S10); IPs escaneo 1.000->2.000 (S14.2.1). Se agregan como referencia NAC 35.000 conexiones (S9.4), DLP 30.000 usuarios (S8.2.2) y estudios de trafico 4 (C13.3), sin modificar las hojas D1/D2.
A46: CONVENCIONES DE COLOR
A47: Texto azul | B47: Entrada modificable (hardcoded input)
A48: Texto negro | B48: Fórmula calculada
A49: Texto verde | B49: Vínculo entre hojas
A50: Fondo verde claro | B50: Total / Subtotal
A51: Fondo azul navy | B51: Gran total / valor final del contrato

Sheet D1. Conectividad
A1: DOMINIO 1 — SERVICIO DE CONECTIVIDAD WAN-LAN (SD-WAN NACIONAL)
A2: Anexo Técnico 1 — Arquitectura SD-WAN activo-activo Bogotá-Cali / Cobertura 876 sedes / IPv6 dual-stack
A4: Ítem | B4: Servicio / Componente | C4: Unidad | D4: Cantidad | E4: Tarifa unitaria mensual (COP) | F4: Meses | G4: Costo total 36 meses (COP) | H4: Observaciones
A5: A. SERVICIO SD-WAN RECURRENTE POR CATEGORÍA DE SEDE
A6: 1 | B6: Servicio Cat 1 — Datacenter / Núcleo SD-WAN (2x5Gbps Internet + 2x5Gbps Datos + 2x canal por nube) | C6: Nodo-mes | D6: ='1. Parámetros'!$B$6 -> 2 | E6: 1.4487518e+08 | F6: ='1. Parámetros'!$B$4 -> 36 | G6: =D6*E6*F6 -> 1.0431013e+10 | H6: Bogotá Salitre + Cali Bunker (activo-activo)
A7: 2 | B7: Servicio Cat 2 — Sedes principales (fibra dedicada con redundancia 1:1, doble carrier) | C7: Sede-mes | D7: ='1. Parámetros'!$B$7 -> 765 | E7: 9580803.2 | F7: ='1. Parámetros'!$B$4 -> 36 | G7: =D7*E7*F7 -> 2.6385532e+11 | H7: 765 sedes en capitales (post-consolidación)
A8: 3 | B8: Servicio Cat 3 — Redes metropolitanas / Ciudades intermedias (MPLS + Internet activo-activo) | C8: Sede-mes | D8: ='1. Parámetros'!$B$8 -> 86 | E8: 2573572.8 | F8: ='1. Parámetros'!$B$4 -> 36 | G8: =D8*E8*F8 -> 7.9677814e+09 | H8: Sedes seccionales en ciudades medianas
A9: 4 | B9: Servicio Cat 4 — Satelital LEO empresarial (zonas sin fibra) | C9: Sede-mes | D9: ='1. Parámetros'!$B$9 -> 25 | E9: 8163887.9 | F9: ='1. Parámetros'!$B$4 -> 36 | G9: =D9*E9*F9 -> 7.3474991e+09 | H9: Tipo Starlink Business / SES-O3b
A10: 5 | B10: Servicio Cat 5 — Interconexión cloud (ExpressRoute + FastConnect + VPN B2B) | C10: Canal-mes | D10: ='1. Parámetros'!$B$10 -> 4 | E10: 42176990 | F10: ='1. Parámetros'!$B$4 -> 36 | G10: =D10*E10*F10 -> 6.0734866e+09 | H10: Azure + OCI (2 canales por nube)
A11: 6 | B11: Servicio Cat 6 — Canales complementarios (Internet respaldo, móvil, WiFi) | C11: Canal-mes | D11: ='1. Parámetros'!$B$11 -> 4 | E11: 1870937.6 | F11: ='1. Parámetros'!$B$4 -> 36 | G11: =D11*E11*F11 -> 2.6941501e+08 | H11: Bolsa de servicios complementarios
A12: Subtotal A — Servicio SD-WAN recurrente | G12: =SUM(G6:G11) -> 2.9594452e+11
A14: B. SERVICIOS Y COMPONENTES ADICIONALES DE CONECTIVIDAD
A15: 1 | B15: Solución móvil LEO para jornadas de descongestión / brigadas de justicia | C15: Kit | D15: 20 | E15: 15662080 | F15: 1 | G15: =D15*E15*F15 -> 313241600 | H15: Pago contra entrega - hardware + activación
A16: 2 | B16: Servicio mensual conectividad LEO móvil (post-instalación) | C16: Kit-mes | D16: 20 | E16: 2736000 | F16: 36 | G16: =D16*E16*F16 -> 1969920000 | H16: Tarifa de servicio una vez activado
A17: 3 | B17: Adquisición y renovación Pool IPv6 /44 + ASN propio FGN | C17: Global | D17: 1 | E17: 45235200 | F17: 1 | G17: =D17*E17*F17 -> 45235200 | H17: Una sola vez - registro LACNIC
A18: 4 | B18: Plataforma de monitoreo Anexo 1 C11 (licenciamiento incluido en CPE) | C18: Servicio-mes | D18: 1 | E18: 71825067 | F18: 36 | G18: =D18*E18*F18 -> 2.5857024e+09 | H18: Observabilidad de red
A19: 5 | B19: Servicio de ampliación de ancho de banda por demanda (bolsa anual) | C19: Bolsa-año | D19: 3 | E19: 114000000 | F19: 1 | G19: =D19*E19*F19 -> 342000000 | H19: Crecimientos según demanda FGN
A20: 6 | B20: Estudios formales de tráfico / capacidad (trimestrales) | C20: Estudio | D20: 12 | E20: 19000000 | F20: 1 | G20: =D20*E20*F20 -> 228000000 | H20: Caracterización 6/12/24 meses por categoría
A21: Subtotal B — Servicios y componentes adicionales | G21: =SUM(G15:G20) -> 5484099200
A23: TOTAL DOMINIO 1 — CONECTIVIDAD WAN-LAN | G23: =G12+G21 -> 3.0142861e+11
F29: 179

Sheet D2. Seguridad
A1: DOMINIO 2 — SEGURIDAD DIGITAL Y CIBERSEGURIDAD (SASE/SSE + SOC 24x7)
A2: Anexo Técnico 2 — Arquitectura SASE/SSE / SOC 24x7 / SIEM-SOAR / EDR-XDR / NAC / PAM / DLP
A4: Ítem | B4: Servicio / Componente | C4: Unidad | D4: Cantidad | E4: Tarifa unitaria mensual (COP) | F4: Meses | G4: Costo total 36 meses (COP) | H4: Observaciones
A5: A. PLATAFORMA SASE/SSE Y PROTECCIÓN PERIMETRAL
A6: 1 | B6: Licenciamiento SASE/SSE por usuario (SWG + CASB + ZTNA + DLP) | C6: Usuario-mes | D6: ='1. Parámetros'!$B$12 -> 30000 | E6: 25080 | F6: ='1. Parámetros'!$B$4 -> 36 | G6: =D6*E6*F6 -> 27086400000 | H6: 30.000 usuarios
A7: 2 | B7: Antimalware + XDR para endpoints (estaciones de trabajo) | C7: Endpoint-mes | D7: ='1. Parámetros'!$B$13 -> 26000 | E7: 17480 | F7: ='1. Parámetros'!$B$4 -> 36 | G7: =D7*E7*F7 -> 16361280000 | H7: 26.000 endpoints
A8: 3 | B8: Antimalware para servidores (Windows / Linux) | C8: Servidor-mes | D8: ='1. Parámetros'!$B$14 -> 500 | E8: 30400 | F8: ='1. Parámetros'!$B$4 -> 36 | G8: =D8*E8*F8 -> 547200000 | H8: 600 servidores
A9: 4 | B9: Protección DDoS y NGFW perimetral (gestionado) | C9: Plataforma-mes | D9: 1 | E9: 60800000 | F9: ='1. Parámetros'!$B$4 -> 36 | G9: =D9*E9*F9 -> 2188800000 | H9: Inspección perímetro a 10 Gbps
A10: 5 | B10: Gestión y administración de WAF Radware existentes | C10: Dispositivo-mes | D10: ='1. Parámetros'!$B$17 -> 4 | E10: 9120000 | F10: ='1. Parámetros'!$B$4 -> 36 | G10: =D10*E10*F10 -> 1313280000 | H10: 4 dispositivos WAF FGN
A11: 6 | B11: WAF como servicio adicional para apps cloud | C11: App-mes | D11: 1 | E11: 6080000 | F11: ='1. Parámetros'!$B$4 -> 36 | G11: =D11*E11*F11 -> 218880000 | H11: Bolsa para apps SaaS críticas
A12: Subtotal A — SASE/SSE y Protección Perimetral | G12: =SUM(G6:G11) -> 47715840000
A14: B. SOC 24x7 — SIEM / SOAR / NDR / PAM / NAC / DLP
A15: 1 | B15: SOC 24x7 — Operación gestionada (turnos N1/N2/N3, runbooks, threat hunting) | C15: Servicio-mes | D15: 1 | E15: 155800000 | F15: ='1. Parámetros'!$B$4 -> 36 | G15: =D15*E15*F15 -> 5608800000 | H15: Centro de Operaciones de Seguridad
A16: 2 | B16: SIEM — Licenciamiento por EPS (eventos por segundo) e ingesta de logs | C16: Plataforma-mes | D16: 1 | E16: 62320000 | F16: ='1. Parámetros'!$B$4 -> 36 | G16: =D16*E16*F16 -> 2243520000 | H16: Ingestión multifuente / retención 36 meses
A17: 3 | B17: SOAR — Plataforma de orquestación y respuesta automatizada | C17: Plataforma-mes | D17: 1 | E17: 19000000 | F17: ='1. Parámetros'!$B$4 -> 36 | G17: =D17*E17*F17 -> 684000000 | H17: Playbooks integrados con ITSM
A18: 4 | B18: NDR — Network Detection & Response (sensores en sedes Cat 1) | C18: Servicio-mes | D18: 1 | E18: 22800000 | F18: ='1. Parámetros'!$B$4 -> 36 | G18: =D18*E18*F18 -> 820800000 | H18: Detección lateral en datacenter
A19: 5 | B19: Monitoreo de activos críticos (1.500 activos monitoreados) | C19: Activo-mes | D19: ='1. Parámetros'!$B$15 -> 1500 | E19: 25840 | F19: ='1. Parámetros'!$B$4 -> 36 | G19: =D19*E19*F19 -> 1395360000 | H19: Servidores, bases de datos, apps misionales
A20: 6 | B20: PAM — Privileged Access Management (gestión de accesos privilegiados) | C20: Servicio-mes | D20: 1 | E20: 43320000 | F20: ='1. Parámetros'!$B$4 -> 36 | G20: =D20*E20*F20 -> 1559520000 | H20: Gestión de cuentas privilegiadas
A21: 7 | B21: NAC — Network Access Control (control de acceso a la red) | C21: Usuario-mes | D21: ='1. Parámetros'!$B$12 -> 30000 | E21: 8740 | F21: ='1. Parámetros'!$B$4 -> 36 | G21: =D21*E21*F21 -> 9439200000 | H21: Integrado con AD/IdP
A22: 8 | B22: DLP — Data Loss Prevention (endpoint + M365 + SSE + Discovery) | C22: Endpoint-mes | D22: ='1. Parámetros'!$B$13 -> 26000 | E22: 15580 | F22: ='1. Parámetros'!$B$4 -> 36 | G22: =D22*E22*F22 -> 14582880000 | H22: Catálogo inicial 25 políticas
A23: 9 | B23: Vigilancia digital Clear/Deep/Dark Web (CTI - Threat Intelligence) | C23: Servicio-mes | D23: 1 | E23: 11400000 | F23: ='1. Parámetros'!$B$4 -> 36 | G23: =D23*E23*F23 -> 410400000 | H23: Monitoreo de marca FGN
A24: 10 | B24: Escaneo recurrente de vulnerabilidades internas | C24: IP-mes | D24: ='1. Parámetros'!$B$16 -> 2000 | E24: 8360 | F24: ='1. Parámetros'!$B$4 -> 36 | G24: =D24*E24*F24 -> 601920000 | H24: 1.000 IPs escaneadas
A25: 11 | B25: Escaneo de vulnerabilidades perímetro/externo | C25: Servicio-mes | D25: 1 | E25: 7600000 | F25: ='1. Parámetros'!$B$4 -> 36 | G25: =D25*E25*F25 -> 273600000 | H25: Activos expuestos a Internet
A26: 12 | B26: Servicio de Correo Seguro (Protección de Correo Electrónico Basada en Nube) | C26: Servicio-mes | D26: 1 | E26: 21280000 | F26: 36 | G26: =D26*E26*F26 -> 766080000 | H26: Correo analizado y seguro
A27: 13 | B27: Pruebas de Penetración (Pentesting) — campañas semestrales | C27: Ejecución | D27: ='1. Parámetros'!$B$26 -> 6 | E27: 26600000 | F27: 1 | G27: =D27*E27*F27 -> 159600000 | H27: 6 campañas / 36 meses (NIST 800-115)
A28: Subtotal B — SOC 24x7 y Servicios Gestionados de Ciberseguridad | G28: =SUM(G15:G27) -> 38545680000
A30: TOTAL DOMINIO 2 — SEGURIDAD DIGITAL Y CIBERSEGURIDAD | G30: =G12+G28 -> 86261520000

Sheet D3. Videoconferencia
A1: DOMINIO 3 — SERVICIO DE VIDEOCONFERENCIA (UCAAS + HARDWARE DE SALAS)
A2: Anexo Técnico 3 — Plataforma UCaaS SaaS/Híbrida / 86 salas / Webinars 2.000+ asistentes / Cert. NDAA
A4: Ítem | B4: Servicio / Componente | C4: Unidad | D4: Cantidad | E4: Tarifa unitaria mensual (COP) | F4: Meses | G4: Costo total 36 meses (COP) | H4: Observaciones
A5: A. PLATAFORMA UCAAS — LICENCIAMIENTO Y SERVICIO RECURRENTE
A6: 1 | B6: Plataforma UCaaS (SaaS/Híbrida) — licenciamiento usuario reuniones estándar | C6: Usuario-mes | D6: ='1. Parámetros'!$B$12 -> 30000 | E6: 21280 | F6: ='1. Parámetros'!$B$4 -> 36 | G6: =D6*E6*F6 -> 22982400000 | H6: 30.000 usuarios FGN
A7: 2 | B7: Licenciamiento Webinar (2.000+ participantes concurrentes) | C7: Plataforma-mes | D7: 1 | E7: 26600000 | F7: ='1. Parámetros'!$B$4 -> 36 | G7: =D7*E7*F7 -> 957600000 | H7: Audiencias virtuales / streaming integrado
A8: 3 | B8: Repositorio de grabaciones con retención permanente y portal | C8: Plataforma-mes | D8: 1 | E8: 36480000 | F8: ='1. Parámetros'!$B$4 -> 36 | G8: =D8*E8*F8 -> 1313280000 | H8: Mediateca + transcripción + DLP integrado
A9: 4 | B9: Soporte técnico en sitio para eventos críticos / 250 servicios/mes | C9: Servicio-mes | D9: 1 | E9: 60040000 | F9: ='1. Parámetros'!$B$4 -> 36 | G9: =D9*E9*F9 -> 2161440000 | H9: Operadores VC (perfil P5 - ver hoja Perfiles)
A10: 5 | B10: Integración con Microsoft Teams + AD/IdP institucional | C10: Plataforma-mes | D10: 1 | E10: 14440000 | F10: ='1. Parámetros'!$B$4 -> 36 | G10: =D10*E10*F10 -> 519840000 | H10: Interoperabilidad UCaaS-Teams
A11: Subtotal A — Plataforma UCaaS | G11: =SUM(G6:G10) -> 27934560000
A13: B. HARDWARE DE SALAS DE VIDEOCONFERENCIA (PAGO CONTRA ENTREGA)
A14: 1 | B14: Solución Tipo 1 — DJT: Pantalla interactiva 55" + 2 cámaras PTZ + 2 micrófonos + tablet + asistente | C14: Solución | D14: ='1. Parámetros'!$B$18 -> 31 | E14: 22800000 | F14: 1 | G14: =D14*E14*F14 -> 706800000 | H14: Justicia Transicional - 31 salas
A15: 2 | B15: Solución Tipo 2 — Auditorios: Códec VC + 2 cámaras PTZ + tablet + asistente | C15: Solución | D15: ='1. Parámetros'!$B$19 -> 7 | E15: 26600000 | F15: 1 | G15: =D15*E15*F15 -> 186200000 | H15: Auditorios principales - 7 salas
A16: 3 | B16: Solución Tipo 3 — Móviles: Códec + 2 PTZ + 4 micrófonos + tablet + asistente + tótem LED 55" | C16: Solución | D16: ='1. Parámetros'!$B$20 -> 3 | E16: 36480000 | F16: 1 | G16: =D16*E16*F16 -> 109440000 | H16: Kit móvil con tótem - 3 unidades
A17: 4 | B17: Solución Tipo 4 — Direcciones: Pantalla interactiva 55" con carro móvil + cámara PTZ + micrófono + tablet | C17: Solución | D17: ='1. Parámetros'!$B$21 -> 45 | E17: 22040000 | F17: 1 | G17: =D17*E17*F17 -> 991800000 | H17: Direcciones y Subdirecciones - 45 salas
A18: 5 | B18: Kit de Soporte (Tipo 1, 3 y 4) — Repuestos y elementos de respaldo | C18: Kit | D18: ='1. Parámetros'!$B$22 -> 7 | E18: 7524000 | F18: 1 | G18: =D18*E18*F18 -> 52668000 | H18: 7 kits de soporte / repuestos
A19: 6 | B19: Instalación, configuración y puesta en marcha de salas | C19: Sala | D19: 86 | E19: 4180000 | F19: 1 | G19: =D19*E19*F19 -> 359480000 | H19: Por cada sala instalada (servicio profesional)
A20: Subtotal B — Hardware de Salas (pago contra entrega) | G20: =SUM(G14:G19) -> 2406388000
A22: TOTAL DOMINIO 3 — VIDEOCONFERENCIA | G22: =G11+G20 -> 30340948000

Sheet D4. Cableado
A1: DOMINIO 4 — CABLEADO ESTRUCTURADO (BOLSA DE PUNTOS CATEGORÍA 6A BLINDADO)
A2: Anexo Técnico 4 — Modalidad bolsa de monto agotable / Pago por punto efectivamente ejecutado
A4: Ítem | B4: Servicio / Componente | C4: Unidad | D4: Cantidad | E4: Tarifa unitaria mensual (COP) | F4: Meses | G4: Costo total 36 meses (COP) | H4: Observaciones
A5: A. BOLSA DE PUNTOS DE CABLEADO (PAGO CONTRA EJECUCIÓN)
A6: 1 | B6: Punto completo de datos Cat 6A blindado (incluye salida datos + toma regulada + toma normal) | C6: Punto | D6: ='1. Parámetros'!$B$24 -> 6000 | E6: 1406000 | F6: 1 | G6: =D6*E6*F6 -> 8436000000 | H6: Bolsa - 6.000 puntos máximos
A7: 2 | B7: Reubicación de punto lógico + eléctrico (cumple condiciones técnicas sin empalmes) | C7: Punto | D7: ='1. Parámetros'!$B$25 -> 1000 | E7: 646000 | F7: 1 | G7: =D7*E7*F7 -> 646000000 | H7: Bolsa - 1.000 puntos máximos
A8: 3 | B8: Punto eléctrico regulado (cuando se requiere solo toma) | C8: Punto | D8: 800 | E8: 342000 | F8: 1 | G8: =D8*E8*F8 -> 273600000 | H8: Bolsa según necesidad - sin contar
A9: 4 | B9: Punto eléctrico normal | C9: Punto | D9: 500 | E9: 144400 | F9: 1 | G9: =D9*E9*F9 -> 72200000 | H9: Bolsa según necesidad - sin contar
A10: 5 | B10: Backbone fibra óptica multimodo OM4 12 hilos por enlace | C10: Enlace | D10: 120 | E10: 4940000 | F10: 1 | G10: =D10*E10*F10 -> 592800000 | H10: Interconexión entre racks (cuando aplica)
A11: 6 | B11: Suministro e instalación de gabinete/rack de comunicaciones | C11: Unidad | D11: 80 | E11: 4180000 | F11: 1 | G11: =D11*E11*F11 -> 334400000 | H11: Bolsa de gabinetes - según diseño
A12: 7 | B12: Sistema de puesta a tierra (TGB/TMGB + medición + caja protección) | C12: Sede | D12: 150 | E12: 1900000 | F12: 1 | G12: =D12*E12*F12 -> 285000000 | H12: Sedes que no cuenten con PAT
A13: 8 | B13: Visita Site Survey por sede (dimensionamiento previo) | C13: Sede | D13: 250 | E13: 684000 | F13: 1 | G13: =D13*E13*F13 -> 171000000 | H13: Previa a intervención
A14: Subtotal A — Bolsa de Puntos y Componentes | G14: =SUM(G6:G13) -> 10811000000
A16: B. MANTENIMIENTO Y ATENCIÓN POR DEMANDA
A17: 1 | B17: Atención de incidentes y requerimientos en cableado (bolsa mensual) | C17: Servicio-mes | D17: 1 | E17: 11400000 | F17: 36 | G17: =D17*E17*F17 -> 410400000 | H17: Soporte correctivo - 36 meses
A18: 2 | B18: Certificación y pruebas de desempeño post-instalación (por sede) | C18: Certificación | D18: 250 | E18: 342000 | F18: 1 | G18: =D18*E18*F18 -> 85500000 | H18: Una por cada sede intervenida
A19: Subtotal B — Mantenimiento y atención por demanda | G19: =SUM(G17:G18) -> 495900000
A21: TOTAL DOMINIO 4 — CABLEADO ESTRUCTURADO | G21: =G14+G19 -> 11306900000

Sheet P6. Perfiles
A1: ANEXO 6 — PERFILES PROFESIONALES DEL PROVEEDOR (36 MESES)
A2: Personal mínimo del contratista para la operación de los 5 dominios — Roles P1 a P7
A4: Ítem | B4: Perfil profesional | C4: Categoría (P1-P7) | D4: Cant. | E4: Dedic. (%) | F4: Salario base mensual (COP) | G4: Factor multip. | H4: Costo mensual total (COP) | I4: Meses | J4: Total perfil 36 meses (COP)
A5: P1 — ROLES ESTRATÉGICOS TRANSVERSALES
A6: 1 | B6: Gerente de Proyecto Presencial (PMP) — Único punto de contacto | C6: P1 | D6: 1 | E6: 1 | F6: 20460000 | G6: ='1. Parámetros'!$B$28 -> 1.85 | H6: =D6*E6*F6*G6 -> 37851000 | I6: ='1. Parámetros'!$B$4 -> 36 | J6: =H6*I6 -> 1362636000
A7: 2 | B7: Director Técnico (TOGAF + ITIL Strategic Leader) | C7: P1 | D7: 1 | E7: 1 | F7: 20460000 | G7: ='1. Parámetros'!$B$28 -> 1.85 | H7: =D7*E7*F7*G7 -> 37851000 | I7: ='1. Parámetros'!$B$4 -> 36 | J7: =H7*I7 -> 1362636000
A8: 3 | B8: Jefe de Servicios (ITIL v4 + PMI) | C8: P1 | D8: 1 | E8: 1 | F8: 17670000 | G8: ='1. Parámetros'!$B$28 -> 1.85 | H8: =D8*E8*F8*G8 -> 32689500 | I8: ='1. Parámetros'!$B$4 -> 36 | J8: =H8*I8 -> 1176822000
A9: 4 | B9: Gestor de Transición (PMP + ITIL Specialist) — Solo M1-M10 | C9: P1 | D9: 1 | E9: 1 | F9: 16740000 | G9: ='1. Parámetros'!$B$28 -> 1.85 | H9: =D9*E9*F9*G9 -> 30969000 | I9: ='1. Parámetros'!$B$27 -> 10 | J9: =H9*I9 -> 3.0969e+08
A10: P2 — PERFILES TÉCNICOS DE CONECTIVIDAD
A11: 5 | B11: Ingeniero Residente Bogotá (turno 1) — 5x12 | C11: P2 | D11: 1 | E11: 1 | F11: 8370000 | G11: ='1. Parámetros'!$B$28 -> 1.85 | H11: =D11*E11*F11*G11 -> 15484500 | I11: ='1. Parámetros'!$B$4 -> 36 | J11: =H11*I11 -> 5.57442e+08
A12: 6 | B12: Ingeniero Residente Bogotá (turno 2) — 5x12 | C12: P2 | D12: 1 | E12: 1 | F12: 8370000 | G12: ='1. Parámetros'!$B$28 -> 1.85 | H12: =D12*E12*F12*G12 -> 15484500 | I12: ='1. Parámetros'!$B$4 -> 36 | J12: =H12*I12 -> 5.57442e+08
A13: 7 | B13: Ingeniero Residente Cali — 5x8 | C13: P2 | D13: 1 | E13: 1 | F13: 8370000 | G13: ='1. Parámetros'!$B$28 -> 1.85 | H13: =D13*E13*F13*G13 -> 15484500 | I13: ='1. Parámetros'!$B$4 -> 36 | J13: =H13*I13 -> 5.57442e+08
A14: 8 | B14: Especialista en Conectividad WAN/SD-WAN (CCNP/JNCIP) | C14: P2 | D14: 2 | E14: 1 | F14: 12090000 | G14: ='1. Parámetros'!$B$28 -> 1.85 | H14: =D14*E14*F14*G14 -> 44733000 | I14: ='1. Parámetros'!$B$4 -> 36 | J14: =H14*I14 -> 1610388000
A15: 9 | B15: Especialista SD-WAN avanzado (orquestador, ADVPN, QoS) | C15: P2 | D15: 1 | E15: 1 | F15: 13020000 | G15: ='1. Parámetros'!$B$28 -> 1.85 | H15: =D15*E15*F15*G15 -> 24087000 | I15: ='1. Parámetros'!$B$4 -> 36 | J15: =H15*I15 -> 867132000
A16: 10 | B16: Ingeniero NOC 7x24 (turnos rotativos) | C16: P2 | D16: 4 | E16: 1 | F16: 6510000 | G16: ='1. Parámetros'!$B$28 -> 1.85 | H16: =D16*E16*F16*G16 -> 48174000 | I16: ='1. Parámetros'!$B$4 -> 36 | J16: =H16*I16 -> 1734264000
A17: P3 — PERFILES TÉCNICOS DE SEGURIDAD (SOC + SASE + DLP + NAC + PAM)
A18: 11 | B18: Gerente de Seguridad (CISSP + ISO 27001 Lead Auditor) | C18: P3 | D18: 1 | E18: 1 | F18: 20460000 | G18: ='1. Parámetros'!$B$28 -> 1.85 | H18: =D18*E18*F18*G18 -> 37851000 | I18: ='1. Parámetros'!$B$4 -> 36 | J18: =H18*I18 -> 1362636000
A19: 12 | B19: Coordinador SOC (GIAC GSOC) | C19: P3 | D19: 1 | E19: 1 | F19: 16740000 | G19: ='1. Parámetros'!$B$28 -> 1.85 | H19: =D19*E19*F19*G19 -> 30969000 | I19: ='1. Parámetros'!$B$4 -> 36 | J19: =H19*I19 -> 1.114884e+09
A20: 13 | B20: Analista SOC N1 — Turnos 7x24 | C20: P3 | D20: 6 | E20: 1 | F20: 6975000 | G20: ='1. Parámetros'!$B$28 -> 1.85 | H20: =D20*E20*F20*G20 -> 77422500 | I20: ='1. Parámetros'!$B$4 -> 36 | J20: =H20*I20 -> 2.78721e+09
A21: 14 | B21: Analista SOC N2 — Threat hunting / casos complejos | C21: P3 | D21: 4 | E21: 1 | F21: 8835000 | G21: ='1. Parámetros'!$B$28 -> 1.85 | H21: =D21*E21*F21*G21 -> 65379000 | I21: ='1. Parámetros'!$B$4 -> 36 | J21: =H21*I21 -> 2353644000
A22: 15 | B22: Analista SOC N3 — Incident response / forensia | C22: P3 | D22: 2 | E22: 1 | F22: 11020500 | G22: ='1. Parámetros'!$B$28 -> 1.85 | H22: =D22*E22*F22*G22 -> 40775850 | I22: ='1. Parámetros'!$B$4 -> 36 | J22: =H22*I22 -> 1467930600
A23: 16 | B23: Especialista SASE/SSE (administración plataforma) | C23: P3 | D23: 1 | E23: 1 | F23: 12555000 | G23: ='1. Parámetros'!$B$28 -> 1.85 | H23: =D23*E23*F23*G23 -> 23226750 | I23: ='1. Parámetros'!$B$4 -> 36 | J23: =H23*I23 -> 836163000
A24: 17 | B24: Operadores de seguridad (NGFW,WAF,DDoS,Antimalware) | C24: P3 | D24: 1 | E24: 1 | F24: 7440000 | G24: ='1. Parámetros'!$B$28 -> 1.85 | H24: =D24*E24*F24*G24 -> 13764000 | I24: ='1. Parámetros'!$B$4 -> 36 | J24: =H24*I24 -> 4.95504e+08
A25: 18 | B25: Especialista DevSecOps (SOAR, CI/CD) | C25: P3 | D25: 1 | E25: 1 | F25: 11160000 | G25: ='1. Parámetros'!$B$28 -> 1.85 | H25: =D25*E25*F25*G25 -> 20646000 | I25: ='1. Parámetros'!$B$4 -> 36 | J25: =H25*I25 -> 743256000
A26: 19 | B26: Especialista EDR/XDR (endpoint security) | C26: P3 | D26: 1 | E26: 1 | F26: 11625000 | G26: ='1. Parámetros'!$B$28 -> 1.85 | H26: =D26*E26*F26*G26 -> 21506250 | I26: ='1. Parámetros'!$B$4 -> 36 | J26: =H26*I26 -> 774225000
A27: 20 | B27: Especialista DLP (M365 + endpoint + SSE) | C27: P3 | D27: 1 | E27: 1 | F27: 11625000 | G27: ='1. Parámetros'!$B$28 -> 1.85 | H27: =D27*E27*F27*G27 -> 21506250 | I27: ='1. Parámetros'!$B$4 -> 36 | J27: =H27*I27 -> 774225000
A28: 21 | B28: Especialista NAC (control de acceso a red) | C28: P3 | D28: 1 | E28: 1 | F28: 12555000 | G28: ='1. Parámetros'!$B$28 -> 1.85 | H28: =D28*E28*F28*G28 -> 23226750 | I28: ='1. Parámetros'!$B$4 -> 36 | J28: =H28*I28 -> 836163000
A29: 22 | B29: Especialista PAM (Privileged Access Management) | C29: P3 | D29: 1 | E29: 1 | F29: 11997000 | G29: ='1. Parámetros'!$B$28 -> 1.85 | H29: =D29*E29*F29*G29 -> 22194450 | I29: ='1. Parámetros'!$B$4 -> 36 | J29: =H29*I29 -> 799000200
A30: 23 | B30: Pentester / Ethical Hacker (OSCP) | C30: P3 | D30: 1 | E30: 0.5 | F30: 17205000 | G30: ='1. Parámetros'!$B$28 -> 1.85 | H30: =D30*E30*F30*G30 -> 15914625 | I30: ='1. Parámetros'!$B$4 -> 36 | J30: =H30*I30 -> 572926500
A31: P4 — PERFILES DE SERVICIOS, MESA DE AYUDA Y OBSERVABILIDAD
A32: 24 | B32: Coordinador de Agentes (Mesa de Ayuda) | C32: P4 | D32: 1 | E32: 1 | F32: 7905000 | G32: ='1. Parámetros'!$B$28 -> 1.85 | H32: =D32*E32*F32*G32 -> 14624250 | I32: ='1. Parámetros'!$B$4 -> 36 | J32: =H32*I32 -> 5.26473e+08
A33: 25 | B33: Agentes Mesa de Ayuda N1 (atención remota) | C33: P4 | D33: 12 | E33: 1 | F33: 4510500 | G33: ='1. Parámetros'!$B$28 -> 1.85 | H33: =D33*E33*F33*G33 -> 100133100 | I33: ='1. Parámetros'!$B$4 -> 36 | J33: =H33*I33 -> 3604791600
A34: 26 | B34: Agentes Mesa de Ayuda N2 (escalamiento) | C34: P4 | D34: 6 | E34: 1 | F34: 6370500 | G34: ='1. Parámetros'!$B$28 -> 1.85 | H34: =D34*E34*F34*G34 -> 70712550 | I34: ='1. Parámetros'!$B$4 -> 36 | J34: =H34*I34 -> 2545651800
A35: 27 | B35: Técnicos de soporte en sitio (presencial sedes Bogotá) | C35: P4 | D35: 8 | E35: 1 | F35: 5115000 | G35: ='1. Parámetros'!$B$28 -> 1.85 | H35: =D35*E35*F35*G35 -> 75702000 | I35: ='1. Parámetros'!$B$4 -> 36 | J35: =H35*I35 -> 2725272000
A36: 28 | B36: Especialista de Observabilidad (Splunk/Elastic/Dynatrace) | C36: P4 | D36: 1 | E36: 1 | F36: 9300000 | G36: ='1. Parámetros'!$B$28 -> 1.85 | H36: =D36*E36*F36*G36 -> 17205000 | I36: ='1. Parámetros'!$B$4 -> 36 | J36: =H36*I36 -> 619380000
A37: P5 — PERFILES TÉCNICOS DE VIDEOCONFERENCIA
A38: 29 | B38: Agentes de Videoconferencia (3 agentes) | C38: P5 | D38: 3 | E38: 1 | F38: 5115000 | G38: ='1. Parámetros'!$B$28 -> 1.85 | H38: =D38*E38*F38*G38 -> 28388250 | I38: ='1. Parámetros'!$B$4 -> 36 | J38: =H38*I38 -> 1021977000
A39: 30 | B39: Operador de Sala VC (CTS AVIXA) — Eventos críticos DJT | C39: P5 | D39: 2 | E39: 1 | F39: 6510000 | G39: ='1. Parámetros'!$B$28 -> 1.85 | H39: =D39*E39*F39*G39 -> 24087000 | I39: ='1. Parámetros'!$B$4 -> 36 | J39: =H39*I39 -> 867132000
A40: 31 | B40: Ingeniero de Plataforma UCaaS (Cisco/Teams/Zoom/Pexip) | C40: P5 | D40: 1 | E40: 1 | F40: 9300000 | G40: ='1. Parámetros'!$B$28 -> 1.85 | H40: =D40*E40*F40*G40 -> 17205000 | I40: ='1. Parámetros'!$B$4 -> 36 | J40: =H40*I40 -> 619380000
A41: P6 — PERFILES TÉCNICOS DE CABLEADO ESTRUCTURADO
...

Sheet GG. Gastos Generales
A1: GASTOS GENERALES, TRANSICIÓN Y ADMINISTRACIÓN DEL CONTRATO
A3: Ítem | B3: Concepto | C3: Unidad | D3: Cantidad | E3: Valor unitario (COP) | F3: Meses | G3: Costo total (COP)
A4: A. PROTOCOLO DE TRANSICIÓN (M1-M10)
A5: 1 | B5: Plan Detallado de Transición (PDT) y documentación de plataforma actual | C5: Entregable | D5: 1 | E5: 26600000 | F5: 1 | G5: =D5*E5*F5 -> 26600000
A6: 2 | B6: Knowledge Transfer del proveedor saliente | C6: Servicio | D6: 1 | E6: 34200000 | F6: 1 | G6: =D6*E6*F6 -> 34200000
A7: 3 | B7: Ambiente de laboratorio / staging para pruebas paralelas | C7: Plataforma | D7: 1 | E7: 60800000 | F7: 1 | G7: =D7*E7*F7 -> 60800000
A8: 4 | B8: Inventario CMDB inicial validado | C8: Entregable | D8: 1 | E8: 19000000 | F8: 1 | G8: =D8*E8*F8 -> 19000000
A9: 5 | B9: Plan de comunicación y gestión del cambio | C9: Plan | D9: 1 | E9: 11400000 | F9: 1 | G9: =D9*E9*F9 -> 11400000
A10: 6 | B10: Doble facturación controlada — operación simultánea (M1-M10) | C10: Mes | D10: 10 | E10: 136800000 | F10: 1 | G10: =D10*E10*F10 -> 1368000000
A11: 7 | B11: Costos de migración por sede (876 sedes × tarifa unitaria) | C11: Sede | D11: 876 | E11: 1140000 | F11: 1 | G11: =D11*E11*F11 -> 998640000
A12: Subtotal A — Protocolo de Transición | G12: =SUM(G5:G11) -> 2518640000
A14: B. PLATAFORMA ITSM, OBSERVABILIDAD Y CMDB INSTITUCIONAL
A15: 1 | B15: Integración con herramienta ITSM institucional (system of record) | C15: Servicio-mes | D15: 1 | E15: 15200000 | F15: 36 | G15: =D15*E15*F15 -> 547200000
A16: 2 | B16: Integración con plataforma Observabilidad FGN (CMDB + monitoreo) | C16: Servicio-mes | D16: 1 | E16: 15200000 | F16: 36 | G16: =D16*E16*F16 -> 547200000
A17: 3 | B17: Reportería ejecutiva y dashboards de ANS | C17: Servicio-mes | D17: 1 | E17: 6080000 | F17: 36 | G17: =D17*E17*F17 -> 218880000
A18: 4 | B18: Gestión de cambios, problemas y CAB | C18: Servicio-mes | D18: 1 | E18: 4560000 | F18: 36 | G18: =D18*E18*F18 -> 164160000
A19: Subtotal B — ITSM, Observabilidad y CMDB | G19: =SUM(G15:G18) -> 1477440000
A21: C. PÓLIZAS, GARANTÍAS Y GASTOS LOGÍSTICOS
A22: 1 | B22: Póliza de cumplimiento (10% del valor del contrato) | C22: Vigencia | D22: 1 | E22: 485000000 | F22: 1 | G22: =D22*E22*F22 -> 485000000
A23: 2 | B23: Póliza de calidad del servicio | C23: Vigencia | D23: 1 | E23: 735000000 | F23: 1 | G23: =D23*E23*F23 -> 735000000
A24: 3 | B24: Póliza de responsabilidad civil extracontractual | C24: Vigencia | D24: 1 | E24: 415000000 | F24: 1 | G24: =D24*E24*F24 -> 415000000
A25: 4 | B25: Póliza de salarios y prestaciones sociales | C25: Vigencia | D25: 1 | E25: 975000000 | F25: 1 | G25: =D25*E25*F25 -> 975000000
A26: 5 | B26: Logística nacional (despliegue y traslados a 876 sedes) | C26: Mes | D26: 1 | E26: 45600000 | F26: 36 | G26: =D26*E26*F26 -> 1641600000
A27: 6 | B27: Bodegaje, fletes, seguros de hardware | C27: Mes | D27: 1 | E27: 19000000 | F27: 36 | G27: =D27*E27*F27 -> 684000000
A28: 7 | B28: Plan de Recuperación ante Desastres y BCP (DR) | C28: Servicio-mes | D28: 1 | E28: 15200000 | F28: 36 | G28: =D28*E28*F28 -> 547200000
A29: 8 | B29: Auditorías ISO 27001 / ISO 22301 / SOC 2 (anuales) | C29: Auditoría | D29: 3 | E29: 19000000 | F29: 1 | G29: =D29*E29*F29 -> 57000000
A30: Subtotal C — Pólizas, Garantías y Logística | G30: =SUM(G22:G29) -> 5539800000
A32: TOTAL GASTOS GENERALES, TRANSICIÓN Y ADMINISTRACIÓN | G32: =G12+G19+G30 -> 9535880000
