Workbook

Sheet Portada
B2: FISCALÍA GENERAL DE LA NACIÓN
B3: Lista de Chequeo. Entrega Completa del Servicio
B4: Anexo Técnico 7.1. Lista de Chequeo Entrega Servicio. Alineado con Anexo Técnico 7. Protocolo de Transición (M1-M10)
B6: Documento alineado con:
B7: • Anexo Técnico 1 (Conectividad 2026)
B8: • Anexo Técnico 1.1 (Matriz de Sedes). Columna ID Nodo como clave primaria.
B9: • Anexo Técnico 7. Protocolo de Transición. Secciones T1 a T13 y Apéndices A-F.
B10: • Anexo Técnico 7. Protocolo de Transición. Cronograma de referencia (Hitos M1-M10).
B11: • Anexo Técnico 5 — Acuerdo de Niveles de Servicio (Catálogo ANS FGN: umbrales, prioridades y penalidades).
B12: • Anexo Técnico 2 (Seguridad Digital y Ciberseguridad). Generalidades — herramienta ITSM institucional.
B13: • Anexo Técnico 6 (Perfiles Profesionales). P2.5, P2.6 y otros.
B15: Fases del proceso:
... B43: 6. La hoja Resumen acumula los indicadores del Reporte Semanal (Anexo Técnico 7. Apéndice D).

Sheet Lista de Chequeo
A1: Fase | B1: ID | C1: Descripción del ítem | D1: Categoría aplicable | E1: Hito | F1: Ref. Anexo 7 (T) | G1: Ref. Otros anexos | H1: Estado | I1: Responsable | J1: Fecha Límite | K1: Evidencia / URL | L1: Sede / ID Nodo (Anexo 1.1) | M1: Observaciones
A2: FASE 1. Planeación e inicio (M1) | D2: Todas
A3: FASE 1. Planeación e inicio (M1) | B3: 8.1 | C3: Designación formal del Gestor de Transición (Anexo 6 P2.5) como punto único de contacto. | D3: Todas | F3: T1.1 | G3: Anexo 6. P2.5
A4: FASE 1. Planeación e inicio (M1) | B4: 8.2 | C4: Designación del Coordinador de Salida del PROVEEDOR SALIENTE (Anexo 6 P2.6). | D4: Todas | F4: T1.1 | G4: Anexo 6. P2.6
A5: FASE 1. Planeación e inicio (M1) | B5: 8.3 | C5: Designación del Supervisor del contrato y del Equipo TIC de FGN para la transición. | D5: Todas | F5: T1.1
A6: FASE 1. Planeación e inicio (M1) | B6: 8.4 | C6: Verificación de Registro TIC vigente del PROVEEDOR ENTRANTE. | D6: Todas | G6: Anexo 1. Calidad
A7: FASE 1. Planeación e inicio (M1) | B7: 7.5 | C7: Acuerdo de Confidencialidad / NDA suscrito entre las partes para Knowledge Transfer. | D7: Todas | E7: M1 | F7: T9.1 | G7: Anexo 1. C17
A8: FASE 1. Planeación e inicio (M1) | B8: 4.6 | C8: Designación de Interventoría con alcance específico sobre el protocolo de transición. | D8: Todas | F8: T1.1
A9: FASE 1. Planeación e inicio (M1) | B9: 4.7 | C9: Knowledge Transfer recibido del PROVEEDOR SALIENTE con actas y videos de sesiones. | D9: Todas | E9: M1 | F9: T1 / T2 | G9: Anexo Técnico 7. RACI
A10: FASE 2. Diseño y aprobación (M1-M2) | B10: 1.1 | C10: Plan Detallado de Transición (PDT). Entregado dentro de M1. | D10: Todas | E10: M2 | F10: T2 (Entregable 1) | G10: Anexo Técnico 7. T2
A11: FASE 2. Diseño y aprobación (M1-M2) | B11: 1.2 | C11: Inventario completo de sedes y servicios a migrar. Entregado en M1, validado contra Anexo 1.1. | D11: Todas | E11: M2 | F11: T2 (Entregable 2) | G11: Anexo 1.1
A12: FASE 2. Diseño y aprobación (M1-M2) | B12: 1.3 | C12: Documentación técnica de la plataforma actual (configs, IPs, políticas, VLAN). Dentro de M1. | D12: Todas | E12: M1 | F12: T2 (Entregable 3)
A13: FASE 2. Diseño y aprobación (M1-M2) | B13: 1.4 | C13: Cronograma de cortes por sede con ventanas de mantenimiento. Dentro de M1. | D13: Todas | E13: M2 | F13: T2 (Entregable 4) | G13: Cronograma maestro
A14: FASE 2. Diseño y aprobación (M1-M2) | B14: 1.5 | C14: Procedimientos de rollback por categoría. Dentro de M1. | D14: Todas | E14: M2 | F14: T2 (Ent. 5) / T12 | G14: Anexo Técnico 7. T12
A15: FASE 2. Diseño y aprobación (M1-M2) | B15: 1.6 | C15: Plan de comunicación y gestión del cambio. Antes del cierre de M2. | D15: Todas | E15: M2 | F15: T2 (Ent. 6) / T6 | G15: Anexo Técnico 7. T6
A16: FASE 2. Diseño y aprobación (M1-M2) | B16: 1.7 | C16: Ambiente de laboratorio/staging para configuración paralela. Antes del cierre de M2. | D16: Todas | E16: M2 | F16: T2 (Entregable 7)
A17: FASE 2. Diseño y aprobación (M1-M2) | B17: 7.7 | C17: Diseño integral SD-WAN (arquitectura activo-activo, VRF/VLAN, segmentación). | D17: Todas | E17: M2 | F17: T2 (Entregable 1) | G17: Anexo 1. C1
A18: FASE 2. Diseño y aprobación (M1-M2) | B18: 5.8 | C18: Plan Detallado de Retiro (PDR) del PROVEEDOR SALIENTE acordado. | D18: Todas | E18: M2 | F18: Anexo Técnico 7. T8 | G18: T2 (Ent. 9) / T8
A19: FASE 2. Diseño y aprobación (M1-M2) | B19: 5.9 | C19: Plataforma de monitoreo principal puesta en funcionamiento. Antes del cierre de M2. | D19: Cat 1 | E19: M3 | F19: T2 (Entregable 8) | G19: Anexo 1. C8
A20: FASE 2. Diseño y aprobación (M1-M2) | B20: 5.10 | C20: Plan de coexistencia formalizado conforme a T3 (división de responsabilidades, facturación, gobierno de cambios). | D20: Todas | E20: M2 | F20: T3 | G20: Anexo Técnico 7. T3
A21: FASE 2. Diseño y aprobación (M1-M2) | B21: 2.12 | C21: Matriz RACI específica de la transición acordada y publicada (T1.2). | D21: Todas | E21: M2 | F21: T1.2 | G21: Anexo 6
A22: FASE 2. Diseño y aprobación (M1-M2) | B22: 2.13 | C22: Catálogo de Riesgos personalizado por el PROVEEDOR ENTRANTE conforme a la taxonomía T5. | D22: Todas | E22: M2 | F22: T5 | G22: ISO 31000
A23: FASE 3. Habilitación nodos Categoría 1 (Datacenters) (M3) | B23: 2.1 | C23: Datacenter Bogotá: 1 canal Internet ≥ 5 Gbps, hand-off independiente. | D23: Cat 1 | E23: M3 | F23: T10.1 | G23: Anexo 1. Cat 1 / C9
A24: FASE 3. Habilitación nodos Categoría 1 (Datacenters) (M3) | B24: 2.2 | C24: Datacenter Cali: 1 canal Internet ≥ 5 Gbps, hand-off independiente. | D24: Cat 1 | E24: M3 | F24: T10.1 | G24: Anexo 1. Cat 1 / C9
A25: FASE 3. Habilitación nodos Categoría 1 (Datacenters) (M3) | B25: 2.3 | C25: 2 canales de datos ≥ 5 Gbps (uno por nodo Bogotá / Cali) operativos. | D25: Cat 1 | E25: M3 | F25: T10.1 | G25: Anexo 1. Cat 1
A26: FASE 3. Habilitación nodos Categoría 1 (Datacenters) (M3) | B26: 2.4 | C26: 2 canales de interconexión dedicada a Azure (ExpressRoute o equivalente). | D26: Cat 1 / Cat 5 | E26: M3 | F26: T10.1 / T10.5 | G26: Anexo 1. Cat 5
A27: FASE 3. Habilitación nodos Categoría 1 (Datacenters) (M3) | B27: 2.5 | C27: 2 canales de interconexión dedicada a OCI (FastConnect o equivalente). | D27: Cat 1 / Cat 5 | E27: M3 | F27: T10.1 / T10.5 | G27: Anexo 1. Cat 5
A28: FASE 3. Habilitación nodos Categoría 1 (Datacenters) (M3) | B28: 2.6 | C28: Modo ACTIVO-ACTIVO funcional entre Bogotá y Cali con balanceo demostrado. | D28: Cat 1 | E28: M3 | F28: T10.1 | G28: Anexo 1. C3.2 / Cat 1
... A30: FASE 3. Habilitación nodos Categoría 1 (Datacenters) (M3) | B30: 2.8 | C30: Switches core Bogotá (HA) y Cali (standalone) configurados y operativos. | D30: Cat 1 | E30: M3 | F30: T10.1 | G30: Anexo 1. C18
A31: FASE 3. Habilitación nodos Categoría 1 (Datacenters) (M3) | B31: 2.9 | C31: Servidor SFTP licenciado, instalado y operativo en el nivel Cat 1. | D31: Cat 1 | E31: M3 | G31: Anexo 1. C3.5
A32: FASE 3. Habilitación nodos Categoría 1 (Datacenters) (M3) | B32: 2.10 | C32: Plataforma ITSM operativa y CMDB inicializada para la transición. | D32: Cat 1 | E32: M3 | F32: T7 / T9.3 | G32: Anexo 2. Generalidades
A33: FASE 3. Habilitación nodos Categoría 1 (Datacenters) (M3) | B33: 2.11 | C33: Inicio de despliegue Categoría 2, primera sede validada en M3 (después de consolidar Cat.1). | D33: Cat 2 | E33: M4 | F33: T10.2 | G33: Anexo 1.1
A34: FASE 4. Implementación por sede Cat.2 a Cat.6 (M4-M8) | B34: 3.1 | C34: Categoría 2. Sedes principales: 1 canal WAN dedicado + 1 canal Internet por sede activa. | D34: Cat 2 | E34: M6 | F34: T10.2 | G34: Anexo 1. C3 / Anexo 1.1
A35: FASE 4. Implementación por sede Cat.2 a Cat.6 (M4-M8) | B35: 3.2 | C35: Categoría 2. CPE SD-WAN instalado, configurado y probado en modo pasivo ≥ 24 h previas. | D35: Cat 2 | E35: M6 | F35: T10.1 / T10.2 | G35: Anexo 1. C1
A36: FASE 4. Implementación por sede Cat.2 a Cat.6 (M4-M8) | B36: 3.3 | C36: Categoría 2. PAT superada por sede y Acta de Activación (Apéndice B) suscrita. | D36: Cat 2 | E36: M6 | F36: T11 / T7 | G36: Anexo Técnico 7. Apéndice B
A37: FASE 4. Implementación por sede Cat.2 a Cat.6 (M4-M8) | B37: 3.4 | C37: Categoría 3. Ciudades intermedias: 1 canal MPLS/IP VPN + 1 Internet por sede activa. | D37: Cat 3 | E37: M6 | F37: T10.3 | G37: Anexo 1. C3 / Cat 3
A38: FASE 4. Implementación por sede Cat.2 a Cat.6 (M4-M8) | B38: 3.5 | C38: Categoría 3. CPE SD-WAN instalado, configurado y probado en modo pasivo ≥ 24 h previas. | D38: Cat 3 | E38: M6 | F38: T10.1 / T10.3
A39: FASE 4. Implementación por sede Cat.2 a Cat.6 (M4-M8) | B39: 3.6 | C39: Categoría 3. PAT superada por sede y Acta de Activación suscrita. | D39: Cat 3 | E39: M6 | F39: T11 / T7 | G39: Anexo Técnico 7. Apéndice B
A40: FASE 4. Implementación por sede Cat.2 a Cat.6 (M4-M8) | B40: 3.7 | C40: Categoría 4. Satelital LEO empresarial integrada al CPE SD-WAN por sede. | D40: Cat 4 | E40: M7 | F40: T10.4 | G40: Anexo 1. Cat 4
A41: FASE 4. Implementación por sede Cat.2 a Cat.6 (M4-M8) | B41: 3.8 | C41: Categoría 4. Terminal LEO certificado por proveedor satelital y configurado. | D41: Cat 4 | E41: M7 | F41: T10.4
...

Sheet Resumen
B2: Resumen de avance. por Fase
B4: # | C4: Fase | D4: Total | E4: Cumplido | F4: En curso | G4: Pendiente | H4: No aplica | I4: Bloqueado | J4: % Cumplimiento
B5: 1 | C5: FASE 1. Planeación e inicio (M1) | D5: =COUNTIF('Lista de Chequeo'!A:A,C5) -> 8 | E5: =COUNTIFS('Lista de Chequeo'!A:A,C5,'Lista de Chequeo'!H:H,"Cumplido") -> 0 | F5: =COUNTIFS('Lista de Chequeo'!A:A,C5,'Lista de Chequeo'!H:H,"En curso") -> 0 | G5: =COUNTIFS('Lista de Chequeo'!A:A,C5,'Lista de Chequeo'!H:H,"Pendiente") -> 0 | H5: =COUNTIFS('Lista de Chequeo'!A:A,C5,'Lista de Chequeo'!H:H,"No aplica") -> 0 | I5: =COUNTIFS('Lista de Chequeo'!A:A,C5,'Lista de Chequeo'!H:H,"Bloqueado") -> 0 | J5: =IFERROR((E5+H5)/(D5-H5+H5),0) -> 0
B6: 2 | C6: FASE 2. Diseño y aprobación (M1-M2) | D6: =COUNTIF('Lista de Chequeo'!A:A,C6) -> 13 | E6: =COUNTIFS('Lista de Chequeo'!A:A,C6,'Lista de Chequeo'!H:H,"Cumplido") -> 0 | F6: =COUNTIFS('Lista de Chequeo'!A:A,C6,'Lista de Chequeo'!H:H,"En curso") -> 0 | G6: =COUNTIFS('Lista de Chequeo'!A:A,C6,'Lista de Chequeo'!H:H,"Pendiente") -> 0 | H6: =COUNTIFS('Lista de Chequeo'!A:A,C6,'Lista de Chequeo'!H:H,"No aplica") -> 0 | I6: =COUNTIFS('Lista de Chequeo'!A:A,C6,'Lista de Chequeo'!H:H,"Bloqueado") -> 0 | J6: =IFERROR((E6+H6)/(D6-H6+H6),0) -> 0
B7: 3 | C7: FASE 3. Habilitación nodos Categoría 1 (Datacenters) (M3) | D7: =COUNTIF('Lista de Chequeo'!A:A,C7) -> 11 | E7: =COUNTIFS('Lista de Chequeo'!A:A,C7,'Lista de Chequeo'!H:H,"Cumplido") -> 0 | F7: =COUNTIFS('Lista de Chequeo'!A:A,C7,'Lista de Chequeo'!H:H,"En curso") -> 0 | G7: =COUNTIFS('Lista de Chequeo'!A:A,C7,'Lista de Chequeo'!H:H,"Pendiente") -> 0 | H7: =COUNTIFS('Lista de Chequeo'!A:A,C7,'Lista de Chequeo'!H:H,"No aplica") -> 0 | I7: =COUNTIFS('Lista de Chequeo'!A:A,C7,'Lista de Chequeo'!H:H,"Bloqueado") -> 0 | J7: =IFERROR((E7+H7)/(D7-H7+H7),0) -> 0
B8: 4 | C8: FASE 4. Implementación por sede Cat.2 a Cat.6 (M4-M8) | D8: =COUNTIF('Lista de Chequeo'!A:A,C8) -> 18 | E8: =COUNTIFS('Lista de Chequeo'!A:A,C8,'Lista de Chequeo'!H:H,"Cumplido") -> 0 | F8: =COUNTIFS('Lista de Chequeo'!A:A,C8,'Lista de Chequeo'!H:H,"En curso") -> 0 | G8: =COUNTIFS('Lista de Chequeo'!A:A,C8,'Lista de Chequeo'!H:H,"Pendiente") -> 0 | H8: =COUNTIFS('Lista de Chequeo'!A:A,C8,'Lista de Chequeo'!H:H,"No aplica") -> 0 | I8: =COUNTIFS('Lista de Chequeo'!A:A,C8,'Lista de Chequeo'!H:H,"Bloqueado") -> 0 | J8: =IFERROR((E8+H8)/(D8-H8+H8),0) -> 0
B9: 5 | C9: FASE 5. Runbook de corte y PAT por sede (M3-M8) | D9: =COUNTIF('Lista de Chequeo'!A:A,C9) -> 16 | E9: =COUNTIFS('Lista de Chequeo'!A:A,C9,'Lista de Chequeo'!H:H,"Cumplido") -> 0 | F9: =COUNTIFS('Lista de Chequeo'!A:A,C9,'Lista de Chequeo'!H:H,"En curso") -> 0 | G9: =COUNTIFS('Lista de Chequeo'!A:A,C9,'Lista de Chequeo'!H:H,"Pendiente") -> 0 | H9: =COUNTIFS('Lista de Chequeo'!A:A,C9,'Lista de Chequeo'!H:H,"No aplica") -> 0 | I9: =COUNTIFS('Lista de Chequeo'!A:A,C9,'Lista de Chequeo'!H:H,"Bloqueado") -> 0 | J9: =IFERROR((E9+H9)/(D9-H9+H9),0) -> 0
B10: 6 | C10: FASE 6. Retirada del PROVEEDOR SALIENTE (M9-M10) | D10: =COUNTIF('Lista de Chequeo'!A:A,C10) -> 7 | E10: =COUNTIFS('Lista de Chequeo'!A:A,C10,'Lista de Chequeo'!H:H,"Cumplido") -> 0 | F10: =COUNTIFS('Lista de Chequeo'!A:A,C10,'Lista de Chequeo'!H:H,"En curso") -> 0 | G10: =COUNTIFS('Lista de Chequeo'!A:A,C10,'Lista de Chequeo'!H:H,"Pendiente") -> 0 | H10: =COUNTIFS('Lista de Chequeo'!A:A,C10,'Lista de Chequeo'!H:H,"No aplica") -> 0 | I10: =COUNTIFS('Lista de Chequeo'!A:A,C10,'Lista de Chequeo'!H:H,"Bloqueado") -> 0 | J10: =IFERROR((E10+H10)/(D10-H10+H10),0) -> 0
B11: 7 | C11: FASE 7. Operación y reportes (mensual) | D11: =COUNTIF('Lista de Chequeo'!A:A,C11) -> 11 | E11: =COUNTIFS('Lista de Chequeo'!A:A,C11,'Lista de Chequeo'!H:H,"Cumplido") -> 0 | F11: =COUNTIFS('Lista de Chequeo'!A:A,C11,'Lista de Chequeo'!H:H,"En curso") -> 0 | G11: =COUNTIFS('Lista de Chequeo'!A:A,C11,'Lista de Chequeo'!H:H,"Pendiente") -> 0 | H11: =COUNTIFS('Lista de Chequeo'!A:A,C11,'Lista de Chequeo'!H:H,"No aplica") -> 0 | I11: =COUNTIFS('Lista de Chequeo'!A:A,C11,'Lista de Chequeo'!H:H,"Bloqueado") -> 0 | J11: =IFERROR((E11+H11)/(D11-H11+H11),0) -> 0
B12: 8 | C12: FASE 8. Cierre del contrato (M10) | D12: =COUNTIF('Lista de Chequeo'!A:A,C12) -> 6 | E12: =COUNTIFS('Lista de Chequeo'!A:A,C12,'Lista de Chequeo'!H:H,"Cumplido") -> 0 | F12: =COUNTIFS('Lista de Chequeo'!A:A,C12,'Lista de Chequeo'!H:H,"En curso") -> 0 | G12: =COUNTIFS('Lista de Chequeo'!A:A,C12,'Lista de Chequeo'!H:H,"Pendiente") -> 0 | H12: =COUNTIFS('Lista de Chequeo'!A:A,C12,'Lista de Chequeo'!H:H,"No aplica") -> 0 | I12: =COUNTIFS('Lista de Chequeo'!A:A,C12,'Lista de Chequeo'!H:H,"Bloqueado") -> 0 | J12: =IFERROR((E12+H12)/(D12-H12+H12),0) -> 0
C13: TOTAL | D13: =COUNTA('Lista de Chequeo'!B2:B91) -> 89 | E13: =COUNTIF('Lista de Chequeo'!H:H,"Cumplido") -> 0 | F13: =COUNTIF('Lista de Chequeo'!H:H,"En curso") -> 0 | G13: =COUNTIF('Lista de Chequeo'!H:H,"Pendiente") -> 0 | H13: =COUNTIF('Lista de Chequeo'!H:H,"No aplica") -> 0 | I13: =COUNTIF('Lista de Chequeo'!H:H,"Bloqueado") -> 0 | J13: =IFERROR(E13/D13,0) -> 0
B16: KPIs Semanales (Anexo Técnico 7. T4 / Apéndice D)
B18: Indicador | C18: Verde | D18: Amarillo | E18: Rojo | F18: Valor actual | G18: Estado | H18: Acción
B19: % sedes migradas (acumulado) | C19: ≥ plan | D19: −10 % del plan | E19: < −10 % | G19: =IF(F19="","",IF(F19<-0.1,"Rojo",IF(F19<0,"Amarillo","Verde"))) | H19: En rojo: replan y comité extraordinario.
B20: Tasa de éxito de cortes | C20: ≥ 95 % | D20: 85-94 % | E20: < 85 % | G20: =IF(F20="","",IF(F20<0.85,"Rojo",IF(F20<0.95,"Amarillo","Verde"))) | H20: En rojo: escalamiento N3 (T6.2).
B21: Tiempo promedio de corte (horas) | C21: ≤ 2 h | D21: 2-3 h | E21: > 3 h | G21: =IF(F21="","",IF(F21>3,"Rojo",IF(F21>2,"Amarillo","Verde"))) | H21: En rojo: auditoría MOP, refuerzo cuadrilla.
B22: % rollbacks sobre total cortes | C22: ≤ 2 % | D22: 2-5 % | E22: > 5 % | G22: =IF(F22="","",IF(F22>0.05,"Rojo",IF(F22>0.02,"Amarillo","Verde"))) | H22: En rojo: pausa de cortes para análisis.
B23: Disponibilidad general sedes | C23: 100 % | D23: 99,5-99,9 % | E23: < 99,5 % | G23: =IF(F23="","",IF(F23<0.995,"Rojo",IF(F23<1,"Amarillo","Verde"))) | H23: En rojo: activación DRP.
B24: Atraso en hitos (semanas) | C24: 0 | D24: 1-2 semanas | E24: > 2 semanas | G24: =IF(F24="","",IF(F24>7,"Rojo",IF(F24>0,"Amarillo","Verde"))) | H24: En rojo: escalamiento N3.

Sheet Categorías
B2: Avance cruzado. Fase x Categoría
B4: Fase / Categoría | C4: Todas | D4: Cat 1 | E4: Cat 2 | F4: Cat 3 | G4: Cat 4 | H4: Cat 5 | I4: Cat 6
B5: FASE 1. Planeación e inicio (M1) | C5: =IFERROR(COUNTIFS('Lista de Chequeo'!A:A,B5,'Lista de Chequeo'!D:D,"*"&"Todas"&"*",'Lista de Chequeo'!H:H,"Cumplido")/MAX(1,COUNTIFS('Lista de Chequeo'!A:A,B5,'Lista de Chequeo'!D:D,"*"&"Todas"&"*")),0) -> 0 | D5: =IFERROR(COUNTIFS('Lista de Chequeo'!A:A,B5,'Lista de Chequeo'!D:D,"*"&"Cat 1"&"*",'Lista de Chequeo'!H:H,"Cumplido")/MAX(1,COUNTIFS('Lista de Chequeo'!A:A,B5,'Lista de Chequeo'!D:D,"*"&"Cat 1"&"*")),0) -> 0 | E5: =IFERROR(COUNTIFS('Lista de Chequeo'!A:A,B5,'Lista de Chequeo'!D:D,"*"&"Cat 2"&"*",'Lista de Chequeo'!H:H,"Cumplido")/MAX(1,COUNTIFS('Lista de Chequeo'!A:A,B5,'Lista de Chequeo'!D:D,"*"&"Cat 2"&"*")),0) -> 0 | F5: =IFERROR(COUNTIFS('Lista de Chequeo'!A:A,B5,'Lista de Chequeo'!D:D,"*"&"Cat 3"&"*",'Lista de Chequeo'!H:H,"Cumplido")/MAX(1,COUNTIFS('Lista de Chequeo'!A:A,B5,'Lista de Chequeo'!D:D,"*"&"Cat 3"&"*")),0) -> 0 | G5: =IFERROR(COUNTIFS('Lista de Chequeo'!A:A,B5,'Lista de Chequeo'!D:D,"*"&"Cat 4"&"*",'Lista de Chequeo'!H:H,"Cumplido")/MAX(1,COUNTIFS('Lista de Chequeo'!A:A,B5,'Lista de Chequeo'!D:D,"*"&"Cat 4"&"*")),0) -> 0 | H5: =IFERROR(COUNTIFS('Lista de Chequeo'!A:A,B5,'Lista de Chequeo'!D:D,"*"&"Cat 5"&"*",'Lista de Chequeo'!H:H,"Cumplido")/MAX(1,COUNTIFS('Lista de Chequeo'!A:A,B5,'Lista de Chequeo'!D:D,"*"&"Cat 5"&"*")),0) -> 0 | I5: =IFERROR(COUNTIFS('Lista de Chequeo'!A:A,B5,'Lista de Chequeo'!D:D,"*"&"Cat 6"&"*",'Lista de Chequeo'!H:H,"Cumplido")/MAX(1,COUNTIFS('Lista de Chequeo'!A:A,B5,'Lista de Chequeo'!D:D,"*"&"Cat 6"&"*")),0) -> 0
B6: FASE 2. Diseño y aprobación (M1-M2) | C6: =IFERROR(COUNTIFS('Lista de Chequeo'!A:A,B6,'Lista de Chequeo'!D:D,"*"&"Todas"&"*",'Lista de Chequeo'!H:H,"Cumplido")/MAX(1,COUNTIFS('Lista de Chequeo'!A:A,B6,'Lista de Chequeo'!D:D,"*"&"Todas"&"*")),0) -> 0 | D6: =IFERROR(COUNTIFS('Lista de Chequeo'!A:A,B6,'Lista de Chequeo'!D:D,"*"&"Cat 1"&"*",'Lista de Chequeo'!H:H,"Cumplido")/MAX(1,COUNTIFS('Lista de Chequeo'!A:A,B6,'Lista de Chequeo'!D:D,"*"&"Cat 1"&"*")),0) -> 0 | E6: =IFERROR(COUNTIFS('Lista de Chequeo'!A:A,B6,'Lista de Chequeo'!D:D,"*"&"Cat 2"&"*",'Lista de Chequeo'!H:H,"Cumplido")/MAX(1,COUNTIFS('Lista de Chequeo'!A:A,B6,'Lista de Chequeo'!D:D,"*"&"Cat 2"&"*")),0) -> 0 | F6: =IFERROR(COUNTIFS('Lista de Chequeo'!A:A,B6,'Lista de Chequeo'!D:D,"*"&"Cat 3"&"*",'Lista de Chequeo'!H:H,"Cumplido")/MAX(1,COUNTIFS('Lista de Chequeo'!A:A,B6,'Lista de Chequeo'!D:D,"*"&"Cat 3"&"*")),0) -> 0 | G6: =IFERROR(COUNTIFS('Lista de Chequeo'!A:A,B6,'Lista de Chequeo'!D:D,"*"&"Cat 4"&"*",'Lista de Chequeo'!H:H,"Cumplido")/MAX(1,COUNTIFS('Lista de Chequeo'!A:A,B6,'Lista de Chequeo'!D:D,"*"&"Cat 4"&"*")),0) -> 0 | H6: =IFERROR(COUNTIFS('Lista de Chequeo'!A:A,B6,'Lista de Chequeo'!D:D,"*"&"Cat 5"&"*",'Lista de Chequeo'!H:H,"Cumplido")/MAX(1,COUNTIFS('Lista de Chequeo'!A:A,B6,'Lista de Chequeo'!D:D,"*"&"Cat 5"&"*")),0) -> 0 | I6: =IFERROR(COUNTIFS('Lista de Chequeo'!A:A,B6,'Lista de Chequeo'!D:D,"*"&"Cat 6"&"*",'Lista de Chequeo'!H:H,"Cumplido")/MAX(1,COUNTIFS('Lista de Chequeo'!A:A,B6,'Lista de Chequeo'!D:D,"*"&"Cat 6"&"*")),0) -> 0
B7: FASE 3. Habilitación nodos Categoría 1 (Datacenters) (M3) | C7: =IFERROR(COUNTIFS('Lista de Chequeo'!A:A,B7,'Lista de Chequeo'!D:D,"*"&"Todas"&"*",'Lista de Chequeo'!H:H,"Cumplido")/MAX(1,COUNTIFS('Lista de Chequeo'!A:A,B7,'Lista de Chequeo'!D:D,"*"&"Todas"&"*")),0) -> 0 | D7: =IFERROR(COUNTIFS('Lista de Chequeo'!A:A,B7,'Lista de Chequeo'!D:D,"*"&"Cat 1"&"*",'Lista de Chequeo'!H:H,"Cumplido")/MAX(1,COUNTIFS('Lista de Chequeo'!A:A,B7,'Lista de Chequeo'!D:D,"*"&"Cat 1"&"*")),0) -> 0 | E7: =IFERROR(COUNTIFS('Lista de Chequeo'!A:A,B7,'Lista de Chequeo'!D:D,"*"&"Cat 2"&"*",'Lista de Chequeo'!H:H,"Cumplido")/MAX(1,COUNTIFS('Lista de Chequeo'!A:A,B7,'Lista de Chequeo'!D:D,"*"&"Cat 2"&"*")),0) -> 0 | F7: =IFERROR(COUNTIFS('Lista de Chequeo'!A:A,B7,'Lista de Chequeo'!D:D,"*"&"Cat 3"&"*",'Lista de Chequeo'!H:H,"Cumplido")/MAX(1,COUNTIFS('Lista de Chequeo'!A:A,B7,'Lista de Chequeo'!D:D,"*"&"Cat 3"&"*")),0) -> 0 | G7: =IFERROR(COUNTIFS('Lista de Chequeo'!A:A,B7,'Lista de Chequeo'!D:D,"*"&"Cat 4"&"*",'Lista de Chequeo'!H:H,"Cumplido")/MAX(1,COUNTIFS('Lista de Chequeo'!A:A,B7,'Lista de Chequeo'!D:D,"*"&"Cat 4"&"*")),0) -> 0 | H7: =IFERROR(COUNTIFS('Lista de Chequeo'!A:A,B7,'Lista de Chequeo'!D:D,"*"&"Cat 5"&"*",'Lista de Chequeo'!H:H,"Cumplido")/MAX(1,COUNTIFS('Lista de Chequeo'!A:A,B7,'Lista de Chequeo'!D:D,"*"&"Cat 5"&"*")),0) -> 0 | I7: =IFERROR(COUNTIFS('Lista de Chequeo'!A:A,B7,'Lista de Chequeo'!D:D,"*"&"Cat 6"&"*",'Lista de Chequeo'!H:H,"Cumplido")/MAX(1,COUNTIFS('Lista de Chequeo'!A:A,B7,'Lista de Chequeo'!D:D,"*"&"Cat 6"&"*")),0) -> 0
B8: FASE 4. Implementación por sede Cat.2 a Cat.6 (M4-M8) | C8: =IFERROR(COUNTIFS('Lista de Chequeo'!A:A,B8,'Lista de Chequeo'!D:D,"*"&"Todas"&"*",'Lista de Chequeo'!H:H,"Cumplido")/MAX(1,COUNTIFS('Lista de Chequeo'!A:A,B8,'Lista de Chequeo'!D:D,"*"&"Todas"&"*")),0) -> 0 | D8: =IFERROR(COUNTIFS('Lista de Chequeo'!A:A,B8,'Lista de Chequeo'!D:D,"*"&"Cat 1"&"*",'Lista de Chequeo'!H:H,"Cumplido")/MAX(1,COUNTIFS('Lista de Chequeo'!A:A,B8,'Lista de Chequeo'!D:D,"*"&"Cat 1"&"*")),0) -> 0 | E8: =IFERROR(COUNTIFS('Lista de Chequeo'!A:A,B8,'Lista de Chequeo'!D:D,"*"&"Cat 2"&"*",'Lista de Chequeo'!H:H,"Cumplido")/MAX(1,COUNTIFS('Lista de Chequeo'!A:A,B8,'Lista de Chequeo'!D:D,"*"&"Cat 2"&"*")),0) -> 0 | F8: =IFERROR(COUNTIFS('Lista de Chequeo'!A:A,B8,'Lista de Chequeo'!D:D,"*"&"Cat 3"&"*",'Lista de Chequeo'!H:H,"Cumplido")/MAX(1,COUNTIFS('Lista de Chequeo'!A:A,B8,'Lista de Chequeo'!D:D,"*"&"Cat 3"&"*")),0) -> 0 | G8: =IFERROR(COUNTIFS('Lista de Chequeo'!A:A,B8,'Lista de Chequeo'!D:D,"*"&"Cat 4"&"*",'Lista de Chequeo'!H:H,"Cumplido")/MAX(1,COUNTIFS('Lista de Chequeo'!A:A,B8,'Lista de Chequeo'!D:D,"*"&"Cat 4"&"*")),0) -> 0 | H8: =IFERROR(COUNTIFS('Lista de Chequeo'!A:A,B8,'Lista de Chequeo'!D:D,"*"&"Cat 5"&"*",'Lista de Chequeo'!H:H,"Cumplido")/MAX(1,COUNTIFS('Lista de Chequeo'!A:A,B8,'Lista de Chequeo'!D:D,"*"&"Cat 5"&"*")),0) -> 0 | I8: =IFERROR(COUNTIFS('Lista de Chequeo'!A:A,B8,'Lista de Chequeo'!D:D,"*"&"Cat 6"&"*",'Lista de Chequeo'!H:H,"Cumplido")/MAX(1,COUNTIFS('Lista de Chequeo'!A:A,B8,'Lista de Chequeo'!D:D,"*"&"Cat 6"&"*")),0) -> 0
B9: FASE 5. Runbook de corte y PAT por sede (M3-M8) | C9: =IFERROR(COUNTIFS('Lista de Chequeo'!A:A,B9,'Lista de Chequeo'!D:D,"*"&"Todas"&"*",'Lista de Chequeo'!H:H,"Cumplido")/MAX(1,COUNTIFS('Lista de Chequeo'!A:A,B9,'Lista de Chequeo'!D:D,"*"&"Todas"&"*")),0) -> 0 | D9: =IFERROR(COUNTIFS('Lista de Chequeo'!A:A,B9,'Lista de Chequeo'!D:D,"*"&"Cat 1"&"*",'Lista de Chequeo'!H:H,"Cumplido")/MAX(1,COUNTIFS('Lista de Chequeo'!A:A,B9,'Lista de Chequeo'!D:D,"*"&"Cat 1"&"*")),0) -> 0 | E9: =IFERROR(COUNTIFS('Lista de Chequeo'!A:A,B9,'Lista de Chequeo'!D:D,"*"&"Cat 2"&"*",'Lista de Chequeo'!H:H,"Cumplido")/MAX(1,COUNTIFS('Lista de Chequeo'!A:A,B9,'Lista de Chequeo'!D:D,"*"&"Cat 2"&"*")),0) -> 0 | F9: =IFERROR(COUNTIFS('Lista de Chequeo'!A:A,B9,'Lista de Chequeo'!D:D,"*"&"Cat 3"&"*",'Lista de Chequeo'!H:H,"Cumplido")/MAX(1,COUNTIFS('Lista de Chequeo'!A:A,B9,'Lista de Chequeo'!D:D,"*"&"Cat 3"&"*")),0) -> 0 | G9: =IFERROR(COUNTIFS('Lista de Chequeo'!A:A,B9,'Lista de Chequeo'!D:D,"*"&"Cat 4"&"*",'Lista de Chequeo'!H:H,"Cumplido")/MAX(1,COUNTIFS('Lista de Chequeo'!A:A,B9,'Lista de Chequeo'!D:D,"*"&"Cat 4"&"*")),0) -> 0 | H9: =IFERROR(COUNTIFS('Lista de Chequeo'!A:A,B9,'Lista de Chequeo'!D:D,"*"&"Cat 5"&"*",'Lista de Chequeo'!H:H,"Cumplido")/MAX(1,COUNTIFS('Lista de Chequeo'!A:A,B9,'Lista de Chequeo'!D:D,"*"&"Cat 5"&"*")),0) -> 0 | I9: =IFERROR(COUNTIFS('Lista de Chequeo'!A:A,B9,'Lista de Chequeo'!D:D,"*"&"Cat 6"&"*",'Lista de Chequeo'!H:H,"Cumplido")/MAX(1,COUNTIFS('Lista de Chequeo'!A:A,B9,'Lista de Chequeo'!D:D,"*"&"Cat 6"&"*")),0) -> 0
B10: FASE 6. Retirada del PROVEEDOR SALIENTE (M9-M10) | C10: =IFERROR(COUNTIFS('Lista de Chequeo'!A:A,B10,'Lista de Chequeo'!D:D,"*"&"Todas"&"*",'Lista de Chequeo'!H:H,"Cumplido")/MAX(1,COUNTIFS('Lista de Chequeo'!A:A,B10,'Lista de Chequeo'!D:D,"*"&"Todas"&"*")),0) -> 0 | D10: =IFERROR(COUNTIFS('Lista de Chequeo'!A:A,B10,'Lista de Chequeo'!D:D,"*"&"Cat 1"&"*",'Lista de Chequeo'!H:H,"Cumplido")/MAX(1,COUNTIFS('Lista de Chequeo'!A:A,B10,'Lista de Chequeo'!D:D,"*"&"Cat 1"&"*")),0) -> 0 | E10: =IFERROR(COUNTIFS('Lista de Chequeo'!A:A,B10,'Lista de Chequeo'!D:D,"*"&"Cat 2"&"*",'Lista de Chequeo'!H:H,"Cumplido")/MAX(1,COUNTIFS('Lista de Chequeo'!A:A,B10,'Lista de Chequeo'!D:D,"*"&"Cat 2"&"*")),0) -> 0 | F10: =IFERROR(COUNTIFS('Lista de Chequeo'!A:A,B10,'Lista de Chequeo'!D:D,"*"&"Cat 3"&"*",'Lista de Chequeo'!H:H,"Cumplido")/MAX(1,COUNTIFS('Lista de Chequeo'!A:A,B10,'Lista de Chequeo'!D:D,"*"&"Cat 3"&"*")),0) -> 0 | G10: =IFERROR(COUNTIFS('Lista de Chequeo'!A:A,B10,'Lista de Chequeo'!D:D,"*"&"Cat 4"&"*",'Lista de Chequeo'!H:H,"Cumplido")/MAX(1,COUNTIFS('Lista de Chequeo'!A:A,B10,'Lista de Chequeo'!D:D,"*"&"Cat 4"&"*")),0) -> 0 | H10: =IFERROR(COUNTIFS('Lista de Chequeo'!A:A,B10,'Lista de Chequeo'!D:D,"*"&"Cat 5"&"*",'Lista de Chequeo'!H:H,"Cumplido")/MAX(1,COUNTIFS('Lista de Chequeo'!A:A,B10,'Lista de Chequeo'!D:D,"*"&"Cat 5"&"*")),0) -> 0 | I10: =IFERROR(COUNTIFS('Lista de Chequeo'!A:A,B10,'Lista de Chequeo'!D:D,"*"&"Cat 6"&"*",'Lista de Chequeo'!H:H,"Cumplido")/MAX(1,COUNTIFS('Lista de Chequeo'!A:A,B10,'Lista de Chequeo'!D:D,"*"&"Cat 6"&"*")),0) -> 0
B11: FASE 7. Operación y reportes (mensual) | C11: =IFERROR(COUNTIFS('Lista de Chequeo'!A:A,B11,'Lista de Chequeo'!D:D,"*"&"Todas"&"*",'Lista de Chequeo'!H:H,"Cumplido")/MAX(1,COUNTIFS('Lista de Chequeo'!A:A,B11,'Lista de Chequeo'!D:D,"*"&"Todas"&"*")),0) -> 0 | D11: =IFERROR(COUNTIFS('Lista de Chequeo'!A:A,B11,'Lista de Chequeo'!D:D,"*"&"Cat 1"&"*",'Lista de Chequeo'!H:H,"Cumplido")/MAX(1,COUNTIFS('Lista de Chequeo'!A:A,B11,'Lista de Chequeo'!D:D,"*"&"Cat 1"&"*")),0) -> 0 | E11: =IFERROR(COUNTIFS('Lista de Chequeo'!A:A,B11,'Lista de Chequeo'!D:D,"*"&"Cat 2"&"*",'Lista de Chequeo'!H:H,"Cumplido")/MAX(1,COUNTIFS('Lista de Chequeo'!A:A,B11,'Lista de Chequeo'!D:D,"*"&"Cat 2"&"*")),0) -> 0 | F11: =IFERROR(COUNTIFS('Lista de Chequeo'!A:A,B11,'Lista de Chequeo'!D:D,"*"&"Cat 3"&"*",'Lista de Chequeo'!H:H,"Cumplido")/MAX(1,COUNTIFS('Lista de Chequeo'!A:A,B11,'Lista de Chequeo'!D:D,"*"&"Cat 3"&"*")),0) -> 0 | G11: =IFERROR(COUNTIFS('Lista de Chequeo'!A:A,B11,'Lista de Chequeo'!D:D,"*"&"Cat 4"&"*",'Lista de Chequeo'!H:H,"Cumplido")/MAX(1,COUNTIFS('Lista de Chequeo'!A:A,B11,'Lista de Chequeo'!D:D,"*"&"Cat 4"&"*")),0) -> 0 | H11: =IFERROR(COUNTIFS('Lista de Chequeo'!A:A,B11,'Lista de Chequeo'!D:D,"*"&"Cat 5"&"*",'Lista de Chequeo'!H:H,"Cumplido")/MAX(1,COUNTIFS('Lista de Chequeo'!A:A,B11,'Lista de Chequeo'!D:D,"*"&"Cat 5"&"*")),0) -> 0 | I11: =IFERROR(COUNTIFS('Lista de Chequeo'!A:A,B11,'Lista de Chequeo'!D:D,"*"&"Cat 6"&"*",'Lista de Chequeo'!H:H,"Cumplido")/MAX(1,COUNTIFS('Lista de Chequeo'!A:A,B11,'Lista de Chequeo'!D:D,"*"&"Cat 6"&"*")),0) -> 0
B12: FASE 8. Cierre del contrato (M10) | C12: =IFERROR(COUNTIFS('Lista de Chequeo'!A:A,B12,'Lista de Chequeo'!D:D,"*"&"Todas"&"*",'Lista de Chequeo'!H:H,"Cumplido")/MAX(1,COUNTIFS('Lista de Chequeo'!A:A,B12,'Lista de Chequeo'!D:D,"*"&"Todas"&"*")),0) -> 0 | D12: =IFERROR(COUNTIFS('Lista de Chequeo'!A:A,B12,'Lista de Chequeo'!D:D,"*"&"Cat 1"&"*",'Lista de Chequeo'!H:H,"Cumplido")/MAX(1,COUNTIFS('Lista de Chequeo'!A:A,B12,'Lista de Chequeo'!D:D,"*"&"Cat 1"&"*")),0) -> 0 | E12: =IFERROR(COUNTIFS('Lista de Chequeo'!A:A,B12,'Lista de Chequeo'!D:D,"*"&"Cat 2"&"*",'Lista de Chequeo'!H:H,"Cumplido")/MAX(1,COUNTIFS('Lista de Chequeo'!A:A,B12,'Lista de Chequeo'!D:D,"*"&"Cat 2"&"*")),0) -> 0 | F12: =IFERROR(COUNTIFS('Lista de Chequeo'!A:A,B12,'Lista de Chequeo'!D:D,"*"&"Cat 3"&"*",'Lista de Chequeo'!H:H,"Cumplido")/MAX(1,COUNTIFS('Lista de Chequeo'!A:A,B12,'Lista de Chequeo'!D:D,"*"&"Cat 3"&"*")),0) -> 0 | G12: =IFERROR(COUNTIFS('Lista de Chequeo'!A:A,B12,'Lista de Chequeo'!D:D,"*"&"Cat 4"&"*",'Lista de Chequeo'!H:H,"Cumplido")/MAX(1,COUNTIFS('Lista de Chequeo'!A:A,B12,'Lista de Chequeo'!D:D,"*"&"Cat 4"&"*")),0) -> 0 | H12: =IFERROR(COUNTIFS('Lista de Chequeo'!A:A,B12,'Lista de Chequeo'!D:D,"*"&"Cat 5"&"*",'Lista de Chequeo'!H:H,"Cumplido")/MAX(1,COUNTIFS('Lista de Chequeo'!A:A,B12,'Lista de Chequeo'!D:D,"*"&"Cat 5"&"*")),0) -> 0 | I12: =IFERROR(COUNTIFS('Lista de Chequeo'!A:A,B12,'Lista de Chequeo'!D:D,"*"&"Cat 6"&"*",'Lista de Chequeo'!H:H,"Cumplido")/MAX(1,COUNTIFS('Lista de Chequeo'!A:A,B12,'Lista de Chequeo'!D:D,"*"&"Cat 6"&"*")),0) -> 0
B15: Leyenda
B16: Cada celda muestra el % de cumplimiento de los ítems aplicables a esa Fase y Categoría (ítems con estado "Cumplido" / ítems aplicables). "Todas" incluye los ítems transversales. Para ítems con varias categorías (p. ej. "Cat 1 / Cat 5") el conteo aplica a todas las categorías que contengan el texto.
